Workbook

Sheet 판정요약
A1: 판정 요약 — 4주 후 페르소나 레벨 격차
A2: 완료 기준: 격차가 '따라잡을 만하다'고 느껴지는가?
A4: 페르소나 | B4: 유형 | C4: Tier | D4: 최종 누적XP | E4: 최종 레벨 | F4: 최소 대비 레벨배수
A5: P1_안움직임 | B5: 거의 안 움직임 | C5: B | D5: =P1_안움직임!$G$51 -> 114.75 | E5: =P1_안움직임!$H$51 -> 1.096062 | F5: =E5/MIN($E$5:$E$9) -> 1
A6: P2_주3걷기 | B6: 주3 걷기 | C6: B | D6: =P2_주3걷기!$G$51 -> 465.375 | E6: =P2_주3걷기!$H$51 -> 2.7874176 | F6: =E6/MIN($E$5:$E$9) -> 2.5431203
A7: P3_주5러너 | B7: 주5 러너 | C7: A | D7: =P3_주5러너!$G$51 -> 2302.8249 | E7: =P3_주5러너!$H$51 -> 8.0942002 | F7: =E7/MIN($E$5:$E$9) -> 7.3848012
A8: P4_헬스만 | B8: 헬스만 | C8: A | D8: =P4_헬스만!$G$51 -> 2108.8125 | E8: =P4_헬스만!$H$51 -> 7.6329423 | F8: =E8/MIN($E$5:$E$9) -> 6.9639693
A9: P5_들쑥날쑥 | B9: 들쑥날쑥 | C9: B | D9: =P5_들쑥날쑥!$G$51 -> 1084.6259 | E9: =P5_들쑥날쑥!$H$51 -> 4.8998935 | F9: =E9/MIN($E$5:$E$9) -> 4.4704528
A11: 최고/최저 레벨 배수 | E11: =MAX(E5:E9)/MIN(E5:E9) -> 7.3848012
A12: 레벨 스프레드(최고-최저) | E12: =MAX(E5:E9)-MIN(E5:E9) -> 6.9981382
A13: 중앙값 레벨 | E13: =MEDIAN(E5:E9) -> 4.8998935

Sheet Params
A1: Project NEXUS — XP 산식 파라미터 (v0.3 근거: MVP.md §5)
A2: 파란 셀만 바꾸면 전체 시트가 재계산됩니다. (이슈 #2 튜닝 레버)
A4: 파라미터 | B4: 이름 | C4: 값
A5: 기본점수 — 걷기 (pt/분) | B5: walkPt | C5: 1
A6: 기본점수 — 러닝 (pt/분) | B6: runPt | C6: 2
A7: 기본점수 — 근력 (pt/분) | B7: strPt | C7: 1.5
A8: 개인계수 하한 | B8: coefMin | C8: 0.8
A9: 개인계수 상한 | B9: coefMax | C9: 1.5
A10: 개인계수 이동평균 창(일) | B10: coefWindow | C10: 14
A11: 신뢰계수 — Tier A(워치) | B11: tierA | C11: 1
A12: 신뢰계수 — Tier B(폰) | B12: tierB | C12: 0.85
A13: 일일 knee (초과분 절반) | B13: dailyKnee | C13: 200
A14: knee 초과분 체감율 | B14: halfRate | C14: 0.5
A15: 일일 하드캡 | B15: dailyCap | C15: 300
A16: 밸런스 보너스 — 최소 활동일 | B16: balActive | C16: 4
... A20: 레벨 지수 k | B20: levelExp | C20: 1.5

Sheet P1_안움직임
A1: 거의 안 움직임 · Tier B(폰) · 시드 baseline=3.21pt/일
A2: 일 | B2: 걷기(분) | C2: 러닝(분) | D2: 근력(분) | E2: 기본점수 | F2: 14일평균 | G2: 개인계수 | H2: 신뢰계수 | I2: raw XP | J2: 일일 XP | K2: 활동 | L2: 주차
A3: 기준 D-14 | E3: 3.21
A4: 기준 D-13 | E4: 3.21
A5: 기준 D-12 | E5: 3.21
A6: 기준 D-11 | E6: 3.21
A7: 기준 D-10 | E7: 3.21
A8: 기준 D-9 | E8: 3.21
A9: 기준 D-8 | E9: 3.21
A10: 기준 D-7 | E10: 3.21
A11: 기준 D-6 | E11: 3.21
A12: 기준 D-5 | E12: 3.21
A13: 기준 D-4 | E13: 3.21
A14: 기준 D-3 | E14: 3.21
... A16: 기준 D-1 | E16: 3.21
A17: 1 | B17: 0 | C17: 0 | D17: 0 | E17: =B17*Params!$C$5+C17*Params!$C$6+D17*Params!$C$7 -> 0 | F17: =AVERAGE(E3:E16) -> 3.21 | G17: =IF(F17<=0,Params!$C$9,MIN(Params!$C$9,MAX(Params!$C$8,E17/F17))) -> 0.8 | H17: =Params!$C$12 -> 0.85 | I17: =E17*G17*H17 -> 0 | J17: =MIN(Params!$C$15,IF(I17<=Params!$C$13,I17,Params!$C$13+(I17-Params!$C$13)*Params!$C$14)) -> 0 | K17: =IF(E17>0,1,0) -> 0 | L17: =ROUNDUP(1/7,0) -> 1
A18: 2 | B18: 12 | C18: 0 | D18: 0 | E18: =B18*Params!$C$5+C18*Params!$C$6+D18*Params!$C$7 -> 12 | F18: =AVERAGE(E4:E17) -> 2.9807143 | G18: =IF(F18<=0,Params!$C$9,MIN(Params!$C$9,MAX(Params!$C$8,E18/F18))) -> 1.5 | H18: =Params!$C$12 -> 0.85 | I18: =E18*G18*H18 -> 15.3 | J18: =MIN(Params!$C$15,IF(I18<=Params!$C$13,I18,Params!$C$13+(I18-Params!$C$13)*Params!$C$14)) -> 15.3 | K18: =IF(E18>0,1,0) -> 1 | L18: =ROUNDUP(2/7,0) -> 1
A19: 3 | B19: 0 | C19: 0 | D19: 0 | E19: =B19*Params!$C$5+C19*Params!$C$6+D19*Params!$C$7 -> 0 | F19: =AVERAGE(E5:E18) -> 3.6085714 | G19: =IF(F19<=0,Params!$C$9,MIN(Params!$C$9,MAX(Params!$C$8,E19/F19))) -> 0.8 | H19: =Params!$C$12 -> 0.85 | I19: =E19*G19*H19 -> 0 | J19: =MIN(Params!$C$15,IF(I19<=Params!$C$13,I19,Params!$C$13+(I19-Params!$C$13)*Params!$C$14)) -> 0 | K19: =IF(E19>0,1,0) -> 0 | L19: =ROUNDUP(3/7,0) -> 1
A20: 4 | B20: 0 | C20: 0 | D20: 0 | E20: =B20*Params!$C$5+C20*Params!$C$6+D20*Params!$C$7 -> 0 | F20: =AVERAGE(E6:E19) -> 3.3792857 | G20: =IF(F20<=0,Params!$C$9,MIN(Params!$C$9,MAX(Params!$C$8,E20/F20))) -> 0.8 | H20: =Params!$C$12 -> 0.85 | I20: =E20*G20*H20 -> 0 | J20: =MIN(Params!$C$15,IF(I20<=Params!$C$13,I20,Params!$C$13+(I20-Params!$C$13)*Params!$C$14)) -> 0 | K20: =IF(E20>0,1,0) -> 0 | L20: =ROUNDUP(4/7,0) -> 1
A21: 5 | B21: 10 | C21: 0 | D21: 0 | E21: =B21*Params!$C$5+C21*Params!$C$6+D21*Params!$C$7 -> 10 | F21: =AVERAGE(E7:E20) -> 3.15 | G21: =IF(F21<=0,Params!$C$9,MIN(Params!$C$9,MAX(Params!$C$8,E21/F21))) -> 1.5 | H21: =Params!$C$12 -> 0.85 | I21: =E21*G21*H21 -> 12.75 | J21: =MIN(Params!$C$15,IF(I21<=Params!$C$13,I21,Params!$C$13+(I21-Params!$C$13)*Params!$C$14)) -> 12.75 | K21: =IF(E21>0,1,0) -> 1 | L21: =ROUNDUP(5/7,0) -> 1
A22: 6 | B22: 0 | C22: 0 | D22: 0 | E22: =B22*Params!$C$5+C22*Params!$C$6+D22*Params!$C$7 -> 0 | F22: =AVERAGE(E8:E21) -> 3.635 | G22: =IF(F22<=0,Params!$C$9,MIN(Params!$C$9,MAX(Params!$C$8,E22/F22))) -> 0.8 | H22: =Params!$C$12 -> 0.85 | I22: =E22*G22*H22 -> 0 | J22: =MIN(Params!$C$15,IF(I22<=Params!$C$13,I22,Params!$C$13+(I22-Params!$C$13)*Params!$C$14)) -> 0 | K22: =IF(E22>0,1,0) -> 0 | L22: =ROUNDUP(6/7,0) -> 1
A23: 7 | B23: 0 | C23: 0 | D23: 0 | E23: =B23*Params!$C$5+C23*Params!$C$6+D23*Params!$C$7 -> 0 | F23: =AVERAGE(E9:E22) -> 3.4057143 | G23: =IF(F23<=0,Params!$C$9,MIN(Params!$C$9,MAX(Params!$C$8,E23/F23))) -> 0.8 | H23: =Params!$C$12 -> 0.85 | I23: =E23*G23*H23 -> 0 | J23: =MIN(Params!$C$15,IF(I23<=Params!$C$13,I23,Params!$C$13+(I23-Params!$C$13)*Params!$C$14)) -> 0 | K23: =IF(E23>0,1,0) -> 0 | L23: =ROUNDUP(7/7,0) -> 1
A24: 8 | B24: 0 | C24: 0 | D24: 0 | E24: =B24*Params!$C$5+C24*Params!$C$6+D24*Params!$C$7 -> 0 | F24: =AVERAGE(E10:E23) -> 3.1764286 | G24: =IF(F24<=0,Params!$C$9,MIN(Params!$C$9,MAX(Params!$C$8,E24/F24))) -> 0.8 | H24: =Params!$C$12 -> 0.85 | I24: =E24*G24*H24 -> 0 | J24: =MIN(Params!$C$15,IF(I24<=Params!$C$13,I24,Params!$C$13+(I24-Params!$C$13)*Params!$C$14)) -> 0 | K24: =IF(E24>0,1,0) -> 0 | L24: =ROUNDUP(8/7,0) -> 2
A25: 9 | B25: 10 | C25: 0 | D25: 0 | E25: =B25*Params!$C$5+C25*Params!$C$6+D25*Params!$C$7 -> 10 | F25: =AVERAGE(E11:E24) -> 2.9471429 | G25: =IF(F25<=0,Params!$C$9,MIN(Params!$C$9,MAX(Params!$C$8,E25/F25))) -> 1.5 | H25: =Params!$C$12 -> 0.85 | I25: =E25*G25*H25 -> 12.75 | J25: =MIN(Params!$C$15,IF(I25<=Params!$C$13,I25,Params!$C$13+(I25-Params!$C$13)*Params!$C$14)) -> 12.75 | K25: =IF(E25>0,1,0) -> 1 | L25: =ROUNDUP(9/7,0) -> 2
A26: 10 | B26: 0 | C26: 0 | D26: 0 | E26: =B26*Params!$C$5+C26*Params!$C$6+D26*Params!$C$7 -> 0 | F26: =AVERAGE(E12:E25) -> 3.4321429 | G26: =IF(F26<=0,Params!$C$9,MIN(Params!$C$9,MAX(Params!$C$8,E26/F26))) -> 0.8 | H26: =Params!$C$12 -> 0.85 | I26: =E26*G26*H26 -> 0 | J26: =MIN(Params!$C$15,IF(I26<=Params!$C$13,I26,Params!$C$13+(I26-Params!$C$13)*Params!$C$14)) -> 0 | K26: =IF(E26>0,1,0) -> 0 | L26: =ROUNDUP(10/7,0) -> 2
A27: 11 | B27: 0 | C27: 0 | D27: 0 | E27: =B27*Params!$C$5+C27*Params!$C$6+D27*Params!$C$7 -> 0 | F27: =AVERAGE(E13:E26) -> 3.2028571 | G27: =IF(F27<=0,Params!$C$9,MIN(Params!$C$9,MAX(Params!$C$8,E27/F27))) -> 0.8 | H27: =Params!$C$12 -> 0.85 | I27: =E27*G27*H27 -> 0 | J27: =MIN(Params!$C$15,IF(I27<=Params!$C$13,I27,Params!$C$13+(I27-Params!$C$13)*Params!$C$14)) -> 0 | K27: =IF(E27>0,1,0) -> 0 | L27: =ROUNDUP(11/7,0) -> 2
A28: 12 | B28: 0 | C28: 0 | D28: 0 | E28: =B28*Params!$C$5+C28*Params!$C$6+D28*Params!$C$7 -> 0 | F28: =AVERAGE(E14:E27) -> 2.9735714 | G28: =IF(F28<=0,Params!$C$9,MIN(Params!$C$9,MAX(Params!$C$8,E28/F28))) -> 0.8 | H28: =Params!$C$12 -> 0.85 | I28: =E28*G28*H28 -> 0 | J28: =MIN(Params!$C$15,IF(I28<=Params!$C$13,I28,Params!$C$13+(I28-Params!$C$13)*Params!$C$14)) -> 0 | K28: =IF(E28>0,1,0) -> 0 | L28: =ROUNDUP(12/7,0) -> 2
A29: 13 | B29: 15 | C29: 0 | D29: 0 | E29: =B29*Params!$C$5+C29*Params!$C$6+D29*Params!$C$7 -> 15 | F29: =AVERAGE(E15:E28) -> 2.7442857 | G29: =IF(F29<=0,Params!$C$9,MIN(Params!$C$9,MAX(Params!$C$8,E29/F29))) -> 1.5 | H29: =Params!$C$12 -> 0.85 | I29: =E29*G29*H29 -> 19.125 | J29: =MIN(Params!$C$15,IF(I29<=Params!$C$13,I29,Params!$C$13+(I29-Params!$C$13)*Params!$C$14)) -> 19.125 | K29: =IF(E29>0,1,0) -> 1 | L29: =ROUNDUP(13/7,0) -> 2
A30: 14 | B30: 0 | C30: 0 | D30: 0 | E30: =B30*Params!$C$5+C30*Params!$C$6+D30*Params!$C$7 -> 0 | F30: =AVERAGE(E16:E29) -> 3.5864286 | G30: =IF(F30<=0,Params!$C$9,MIN(Params!$C$9,MAX(Params!$C$8,E30/F30))) -> 0.8 | H30: =Params!$C$12 -> 0.85 | I30: =E30*G30*H30 -> 0 | J30: =MIN(Params!$C$15,IF(I30<=Params!$C$13,I30,Params!$C$13+(I30-Params!$C$13)*Params!$C$14)) -> 0 | K30: =IF(E30>0,1,0) -> 0 | L30: =ROUNDUP(14/7,0) -> 2
A31: 15 | B31: 0 | C31: 0 | D31: 0 | E31: =B31*Params!$C$5+C31*Params!$C$6+D31*Params!$C$7 -> 0 | F31: =AVERAGE(E17:E30) -> 3.3571429 | G31: =IF(F31<=0,Params!$C$9,MIN(Params!$C$9,MAX(Params!$C$8,E31/F31))) -> 0.8 | H31: =Params!$C$12 -> 0.85 | I31: =E31*G31*H31 -> 0 | J31: =MIN(Params!$C$15,IF(I31<=Params!$C$13,I31,Params!$C$13+(I31-Params!$C$13)*Params!$C$14)) -> 0 | K31: =IF(E31>0,1,0) -> 0 | L31: =ROUNDUP(15/7,0) -> 3
A32: 16 | B32: 0 | C32: 0 | D32: 0 | E32: =B32*Params!$C$5+C32*Params!$C$6+D32*Params!$C$7 -> 0 | F32: =AVERAGE(E18:E31) -> 3.3571429 | G32: =IF(F32<=0,Params!$C$9,MIN(Params!$C$9,MAX(Params!$C$8,E32/F32))) -> 0.8 | H32: =Params!$C$12 -> 0.85 | I32: =E32*G32*H32 -> 0 | J32: =MIN(Params!$C$15,IF(I32<=Params!$C$13,I32,Params!$C$13+(I32-Params!$C$13)*Params!$C$14)) -> 0 | K32: =IF(E32>0,1,0) -> 0 | L32: =ROUNDUP(16/7,0) -> 3
A33: 17 | B33: 13 | C33: 0 | D33: 0 | E33: =B33*Params!$C$5+C33*Params!$C$6+D33*Params!$C$7 -> 13 | F33: =AVERAGE(E19:E32) -> 2.5 | G33: =IF(F33<=0,Params!$C$9,MIN(Params!$C$9,MAX(Params!$C$8,E33/F33))) -> 1.5 | H33: =Params!$C$12 -> 0.85 | I33: =E33*G33*H33 -> 16.575 | J33: =MIN(Params!$C$15,IF(I33<=Params!$C$13,I33,Params!$C$13+(I33-Params!$C$13)*Params!$C$14)) -> 16.575 | K33: =IF(E33>0,1,0) -> 1 | L33: =ROUNDUP(17/7,0) -> 3
A34: 18 | B34: 0 | C34: 0 | D34: 0 | E34: =B34*Params!$C$5+C34*Params!$C$6+D34*Params!$C$7 -> 0 | F34: =AVERAGE(E20:E33) -> 3.4285714 | G34: =IF(F34<=0,Params!$C$9,MIN(Params!$C$9,MAX(Params!$C$8,E34/F34))) -> 0.8 | H34: =Params!$C$12 -> 0.85 | I34: =E34*G34*H34 -> 0 | J34: =MIN(Params!$C$15,IF(I34<=Params!$C$13,I34,Params!$C$13+(I34-Params!$C$13)*Params!$C$14)) -> 0 | K34: =IF(E34>0,1,0) -> 0 | L34: =ROUNDUP(18/7,0) -> 3
A35: 19 | B35: 10 | C35: 0 | D35: 0 | E35: =B35*Params!$C$5+C35*Params!$C$6+D35*Params!$C$7 -> 10 | F35: =AVERAGE(E21:E34) -> 3.4285714 | G35: =IF(F35<=0,Params!$C$9,MIN(Params!$C$9,MAX(Params!$C$8,E35/F35))) -> 1.5 | H35: =Params!$C$12 -> 0.85 | I35: =E35*G35*H35 -> 12.75 | J35: =MIN(Params!$C$15,IF(I35<=Params!$C$13,I35,Params!$C$13+(I35-Params!$C$13)*Params!$C$14)) -> 12.75 | K35: =IF(E35>0,1,0) -> 1 | L35: =ROUNDUP(19/7,0) -> 3
A36: 20 | B36: 0 | C36: 0 | D36: 0 | E36: =B36*Params!$C$5+C36*Params!$C$6+D36*Params!$C$7 -> 0 | F36: =AVERAGE(E22:E35) -> 3.4285714 | G36: =IF(F36<=0,Params!$C$9,MIN(Params!$C$9,MAX(Params!$C$8,E36/F36))) -> 0.8 | H36: =Params!$C$12 -> 0.85 | I36: =E36*G36*H36 -> 0 | J36: =MIN(Params!$C$15,IF(I36<=Params!$C$13,I36,Params!$C$13+(I36-Params!$C$13)*Params!$C$14)) -> 0 | K36: =IF(E36>0,1,0) -> 0 | L36: =ROUNDUP(20/7,0) -> 3
A37: 21 | B37: 0 | C37: 0 | D37: 0 | E37: =B37*Params!$C$5+C37*Params!$C$6+D37*Params!$C$7 -> 0 | F37: =AVERAGE(E23:E36) -> 3.4285714 | G37: =IF(F37<=0,Params!$C$9,MIN(Params!$C$9,MAX(Params!$C$8,E37/F37))) -> 0.8 | H37: =Params!$C$12 -> 0.85 | I37: =E37*G37*H37 -> 0 | J37: =MIN(Params!$C$15,IF(I37<=Params!$C$13,I37,Params!$C$13+(I37-Params!$C$13)*Params!$C$14)) -> 0 | K37: =IF(E37>0,1,0) -> 0 | L37: =ROUNDUP(21/7,0) -> 3
A38: 22 | B38: 0 | C38: 0 | D38: 0 | E38: =B38*Params!$C$5+C38*Params!$C$6+D38*Params!$C$7 -> 0 | F38: =AVERAGE(E24:E37) -> 3.4285714 | G38: =IF(F38<=0,Params!$C$9,MIN(Params!$C$9,MAX(Params!$C$8,E38/F38))) -> 0.8 | H38: =Params!$C$12 -> 0.85 | I38: =E38*G38*H38 -> 0 | J38: =MIN(Params!$C$15,IF(I38<=Params!$C$13,I38,Params!$C$13+(I38-Params!$C$13)*Params!$C$14)) -> 0 | K38: =IF(E38>0,1,0) -> 0 | L38: =ROUNDUP(22/7,0) -> 4
A39: 23 | B39: 12 | C39: 0 | D39: 0 | E39: =B39*Params!$C$5+C39*Params!$C$6+D39*Params!$C$7 -> 12 | F39: =AVERAGE(E25:E38) -> 3.4285714 | G39: =IF(F39<=0,Params!$C$9,MIN(Params!$C$9,MAX(Params!$C$8,E39/F39))) -> 1.5 | H39: =Params!$C$12 -> 0.85 | I39: =E39*G39*H39 -> 15.3 | J39: =MIN(Params!$C$15,IF(I39<=Params!$C$13,I39,Params!$C$13+(I39-Params!$C$13)*Params!$C$14)) -> 15.3 | K39: =IF(E39>0,1,0) -> 1 | L39: =ROUNDUP(23/7,0) -> 4
A40: 24 | B40: 0 | C40: 0 | D40: 0 | E40: =B40*Params!$C$5+C40*Params!$C$6+D40*Params!$C$7 -> 0 | F40: =AVERAGE(E26:E39) -> 3.5714286 | G40: =IF(F40<=0,Params!$C$9,MIN(Params!$C$9,MAX(Params!$C$8,E40/F40))) -> 0.8 | H40: =Params!$C$12 -> 0.85 | I40: =E40*G40*H40 -> 0 | J40: =MIN(Params!$C$15,IF(I40<=Params!$C$13,I40,Params!$C$13+(I40-Params!$C$13)*Params!$C$14)) -> 0 | K40: =IF(E40>0,1,0) -> 0 | L40: =ROUNDUP(24/7,0) -> 4
A41: 25 | B41: 0 | C41: 0 | D41: 0 | E41: =B41*Params!$C$5+C41*Params!$C$6+D41*Params!$C$7 -> 0 | F41: =AVERAGE(E27:E40) -> 3.5714286 | G41: =IF(F41<=0,Params!$C$9,MIN(Params!$C$9,MAX(Params!$C$8,E41/F41))) -> 0.8 | H41: =Params!$C$12 -> 0.85 | I41: =E41*G41*H41 -> 0 | J41: =MIN(Params!$C$15,IF(I41<=Params!$C$13,I41,Params!$C$13+(I41-Params!$C$13)*Params!$C$14)) -> 0 | K41: =IF(E41>0,1,0) -> 0 | L41: =ROUNDUP(25/7,0) -> 4
...

Sheet P2_주3걷기
A1: 주3 걷기 · Tier B(폰) · 시드 baseline=13.04pt/일
A2: 일 | B2: 걷기(분) | C2: 러닝(분) | D2: 근력(분) | E2: 기본점수 | F2: 14일평균 | G2: 개인계수 | H2: 신뢰계수 | I2: raw XP | J2: 일일 XP | K2: 활동 | L2: 주차
A3: 기준 D-14 | E3: 13.04
A4: 기준 D-13 | E4: 13.04
A5: 기준 D-12 | E5: 13.04
A6: 기준 D-11 | E6: 13.04
A7: 기준 D-10 | E7: 13.04
A8: 기준 D-9 | E8: 13.04
A9: 기준 D-8 | E9: 13.04
A10: 기준 D-7 | E10: 13.04
A11: 기준 D-6 | E11: 13.04
A12: 기준 D-5 | E12: 13.04
A13: 기준 D-4 | E13: 13.04
A14: 기준 D-3 | E14: 13.04
... A16: 기준 D-1 | E16: 13.04
A17: 1 | B17: 30 | C17: 0 | D17: 0 | E17: =B17*Params!$C$5+C17*Params!$C$6+D17*Params!$C$7 -> 30 | F17: =AVERAGE(E3:E16) -> 13.04 | G17: =IF(F17<=0,Params!$C$9,MIN(Params!$C$9,MAX(Params!$C$8,E17/F17))) -> 1.5 | H17: =Params!$C$12 -> 0.85 | I17: =E17*G17*H17 -> 38.25 | J17: =MIN(Params!$C$15,IF(I17<=Params!$C$13,I17,Params!$C$13+(I17-Params!$C$13)*Params!$C$14)) -> 38.25 | K17: =IF(E17>0,1,0) -> 1 | L17: =ROUNDUP(1/7,0) -> 1
A18: 2 | B18: 0 | C18: 0 | D18: 0 | E18: =B18*Params!$C$5+C18*Params!$C$6+D18*Params!$C$7 -> 0 | F18: =AVERAGE(E4:E17) -> 14.251429 | G18: =IF(F18<=0,Params!$C$9,MIN(Params!$C$9,MAX(Params!$C$8,E18/F18))) -> 0.8 | H18: =Params!$C$12 -> 0.85 | I18: =E18*G18*H18 -> 0 | J18: =MIN(Params!$C$15,IF(I18<=Params!$C$13,I18,Params!$C$13+(I18-Params!$C$13)*Params!$C$14)) -> 0 | K18: =IF(E18>0,1,0) -> 0 | L18: =ROUNDUP(2/7,0) -> 1
A19: 3 | B19: 30 | C19: 0 | D19: 0 | E19: =B19*Params!$C$5+C19*Params!$C$6+D19*Params!$C$7 -> 30 | F19: =AVERAGE(E5:E18) -> 13.32 | G19: =IF(F19<=0,Params!$C$9,MIN(Params!$C$9,MAX(Params!$C$8,E19/F19))) -> 1.5 | H19: =Params!$C$12 -> 0.85 | I19: =E19*G19*H19 -> 38.25 | J19: =MIN(Params!$C$15,IF(I19<=Params!$C$13,I19,Params!$C$13+(I19-Params!$C$13)*Params!$C$14)) -> 38.25 | K19: =IF(E19>0,1,0) -> 1 | L19: =ROUNDUP(3/7,0) -> 1
A20: 4 | B20: 0 | C20: 0 | D20: 0 | E20: =B20*Params!$C$5+C20*Params!$C$6+D20*Params!$C$7 -> 0 | F20: =AVERAGE(E6:E19) -> 14.531429 | G20: =IF(F20<=0,Params!$C$9,MIN(Params!$C$9,MAX(Params!$C$8,E20/F20))) -> 0.8 | H20: =Params!$C$12 -> 0.85 | I20: =E20*G20*H20 -> 0 | J20: =MIN(Params!$C$15,IF(I20<=Params!$C$13,I20,Params!$C$13+(I20-Params!$C$13)*Params!$C$14)) -> 0 | K20: =IF(E20>0,1,0) -> 0 | L20: =ROUNDUP(4/7,0) -> 1
A21: 5 | B21: 30 | C21: 0 | D21: 0 | E21: =B21*Params!$C$5+C21*Params!$C$6+D21*Params!$C$7 -> 30 | F21: =AVERAGE(E7:E20) -> 13.6 | G21: =IF(F21<=0,Params!$C$9,MIN(Params!$C$9,MAX(Params!$C$8,E21/F21))) -> 1.5 | H21: =Params!$C$12 -> 0.85 | I21: =E21*G21*H21 -> 38.25 | J21: =MIN(Params!$C$15,IF(I21<=Params!$C$13,I21,Params!$C$13+(I21-Params!$C$13)*Params!$C$14)) -> 38.25 | K21: =IF(E21>0,1,0) -> 1 | L21: =ROUNDUP(5/7,0) -> 1
A22: 6 | B22: 0 | C22: 0 | D22: 0 | E22: =B22*Params!$C$5+C22*Params!$C$6+D22*Params!$C$7 -> 0 | F22: =AVERAGE(E8:E21) -> 14.811429 | G22: =IF(F22<=0,Params!$C$9,MIN(Params!$C$9,MAX(Params!$C$8,E22/F22))) -> 0.8 | H22: =Params!$C$12 -> 0.85 | I22: =E22*G22*H22 -> 0 | J22: =MIN(Params!$C$15,IF(I22<=Params!$C$13,I22,Params!$C$13+(I22-Params!$C$13)*Params!$C$14)) -> 0 | K22: =IF(E22>0,1,0) -> 0 | L22: =ROUNDUP(6/7,0) -> 1
A23: 7 | B23: 0 | C23: 0 | D23: 0 | E23: =B23*Params!$C$5+C23*Params!$C$6+D23*Params!$C$7 -> 0 | F23: =AVERAGE(E9:E22) -> 13.88 | G23: =IF(F23<=0,Params!$C$9,MIN(Params!$C$9,MAX(Params!$C$8,E23/F23))) -> 0.8 | H23: =Params!$C$12 -> 0.85 | I23: =E23*G23*H23 -> 0 | J23: =MIN(Params!$C$15,IF(I23<=Params!$C$13,I23,Params!$C$13+(I23-Params!$C$13)*Params!$C$14)) -> 0 | K23: =IF(E23>0,1,0) -> 0 | L23: =ROUNDUP(7/7,0) -> 1
A24: 8 | B24: 0 | C24: 0 | D24: 0 | E24: =B24*Params!$C$5+C24*Params!$C$6+D24*Params!$C$7 -> 0 | F24: =AVERAGE(E10:E23) -> 12.948571 | G24: =IF(F24<=0,Params!$C$9,MIN(Params!$C$9,MAX(Params!$C$8,E24/F24))) -> 0.8 | H24: =Params!$C$12 -> 0.85 | I24: =E24*G24*H24 -> 0 | J24: =MIN(Params!$C$15,IF(I24<=Params!$C$13,I24,Params!$C$13+(I24-Params!$C$13)*Params!$C$14)) -> 0 | K24: =IF(E24>0,1,0) -> 0 | L24: =ROUNDUP(8/7,0) -> 2
A25: 9 | B25: 30 | C25: 0 | D25: 0 | E25: =B25*Params!$C$5+C25*Params!$C$6+D25*Params!$C$7 -> 30 | F25: =AVERAGE(E11:E24) -> 12.017143 | G25: =IF(F25<=0,Params!$C$9,MIN(Params!$C$9,MAX(Params!$C$8,E25/F25))) -> 1.5 | H25: =Params!$C$12 -> 0.85 | I25: =E25*G25*H25 -> 38.25 | J25: =MIN(Params!$C$15,IF(I25<=Params!$C$13,I25,Params!$C$13+(I25-Params!$C$13)*Params!$C$14)) -> 38.25 | K25: =IF(E25>0,1,0) -> 1 | L25: =ROUNDUP(9/7,0) -> 2
A26: 10 | B26: 0 | C26: 0 | D26: 0 | E26: =B26*Params!$C$5+C26*Params!$C$6+D26*Params!$C$7 -> 0 | F26: =AVERAGE(E12:E25) -> 13.228571 | G26: =IF(F26<=0,Params!$C$9,MIN(Params!$C$9,MAX(Params!$C$8,E26/F26))) -> 0.8 | H26: =Params!$C$12 -> 0.85 | I26: =E26*G26*H26 -> 0 | J26: =MIN(Params!$C$15,IF(I26<=Params!$C$13,I26,Params!$C$13+(I26-Params!$C$13)*Params!$C$14)) -> 0 | K26: =IF(E26>0,1,0) -> 0 | L26: =ROUNDUP(10/7,0) -> 2
A27: 11 | B27: 32 | C27: 0 | D27: 0 | E27: =B27*Params!$C$5+C27*Params!$C$6+D27*Params!$C$7 -> 32 | F27: =AVERAGE(E13:E26) -> 12.297143 | G27: =IF(F27<=0,Params!$C$9,MIN(Params!$C$9,MAX(Params!$C$8,E27/F27))) -> 1.5 | H27: =Params!$C$12 -> 0.85 | I27: =E27*G27*H27 -> 40.8 | J27: =MIN(Params!$C$15,IF(I27<=Params!$C$13,I27,Params!$C$13+(I27-Params!$C$13)*Params!$C$14)) -> 40.8 | K27: =IF(E27>0,1,0) -> 1 | L27: =ROUNDUP(11/7,0) -> 2
A28: 12 | B28: 0 | C28: 0 | D28: 0 | E28: =B28*Params!$C$5+C28*Params!$C$6+D28*Params!$C$7 -> 0 | F28: =AVERAGE(E14:E27) -> 13.651429 | G28: =IF(F28<=0,Params!$C$9,MIN(Params!$C$9,MAX(Params!$C$8,E28/F28))) -> 0.8 | H28: =Params!$C$12 -> 0.85 | I28: =E28*G28*H28 -> 0 | J28: =MIN(Params!$C$15,IF(I28<=Params!$C$13,I28,Params!$C$13+(I28-Params!$C$13)*Params!$C$14)) -> 0 | K28: =IF(E28>0,1,0) -> 0 | L28: =ROUNDUP(12/7,0) -> 2
A29: 13 | B29: 30 | C29: 0 | D29: 0 | E29: =B29*Params!$C$5+C29*Params!$C$6+D29*Params!$C$7 -> 30 | F29: =AVERAGE(E15:E28) -> 12.72 | G29: =IF(F29<=0,Params!$C$9,MIN(Params!$C$9,MAX(Params!$C$8,E29/F29))) -> 1.5 | H29: =Params!$C$12 -> 0.85 | I29: =E29*G29*H29 -> 38.25 | J29: =MIN(Params!$C$15,IF(I29<=Params!$C$13,I29,Params!$C$13+(I29-Params!$C$13)*Params!$C$14)) -> 38.25 | K29: =IF(E29>0,1,0) -> 1 | L29: =ROUNDUP(13/7,0) -> 2
A30: 14 | B30: 0 | C30: 0 | D30: 0 | E30: =B30*Params!$C$5+C30*Params!$C$6+D30*Params!$C$7 -> 0 | F30: =AVERAGE(E16:E29) -> 13.931429 | G30: =IF(F30<=0,Params!$C$9,MIN(Params!$C$9,MAX(Params!$C$8,E30/F30))) -> 0.8 | H30: =Params!$C$12 -> 0.85 | I30: =E30*G30*H30 -> 0 | J30: =MIN(Params!$C$15,IF(I30<=Params!$C$13,I30,Params!$C$13+(I30-Params!$C$13)*Params!$C$14)) -> 0 | K30: =IF(E30>0,1,0) -> 0 | L30: =ROUNDUP(14/7,0) -> 2
A31: 15 | B31: 30 | C31: 0 | D31: 0 | E31: =B31*Params!$C$5+C31*Params!$C$6+D31*Params!$C$7 -> 30 | F31: =AVERAGE(E17:E30) -> 13 | G31: =IF(F31<=0,Params!$C$9,MIN(Params!$C$9,MAX(Params!$C$8,E31/F31))) -> 1.5 | H31: =Params!$C$12 -> 0.85 | I31: =E31*G31*H31 -> 38.25 | J31: =MIN(Params!$C$15,IF(I31<=Params!$C$13,I31,Params!$C$13+(I31-Params!$C$13)*Params!$C$14)) -> 38.25 | K31: =IF(E31>0,1,0) -> 1 | L31: =ROUNDUP(15/7,0) -> 3
A32: 16 | B32: 0 | C32: 0 | D32: 0 | E32: =B32*Params!$C$5+C32*Params!$C$6+D32*Params!$C$7 -> 0 | F32: =AVERAGE(E18:E31) -> 13 | G32: =IF(F32<=0,Params!$C$9,MIN(Params!$C$9,MAX(Params!$C$8,E32/F32))) -> 0.8 | H32: =Params!$C$12 -> 0.85 | I32: =E32*G32*H32 -> 0 | J32: =MIN(Params!$C$15,IF(I32<=Params!$C$13,I32,Params!$C$13+(I32-Params!$C$13)*Params!$C$14)) -> 0 | K32: =IF(E32>0,1,0) -> 0 | L32: =ROUNDUP(16/7,0) -> 3
A33: 17 | B33: 28 | C33: 0 | D33: 0 | E33: =B33*Params!$C$5+C33*Params!$C$6+D33*Params!$C$7 -> 28 | F33: =AVERAGE(E19:E32) -> 13 | G33: =IF(F33<=0,Params!$C$9,MIN(Params!$C$9,MAX(Params!$C$8,E33/F33))) -> 1.5 | H33: =Params!$C$12 -> 0.85 | I33: =E33*G33*H33 -> 35.7 | J33: =MIN(Params!$C$15,IF(I33<=Params!$C$13,I33,Params!$C$13+(I33-Params!$C$13)*Params!$C$14)) -> 35.7 | K33: =IF(E33>0,1,0) -> 1 | L33: =ROUNDUP(17/7,0) -> 3
A34: 18 | B34: 0 | C34: 0 | D34: 0 | E34: =B34*Params!$C$5+C34*Params!$C$6+D34*Params!$C$7 -> 0 | F34: =AVERAGE(E20:E33) -> 12.857143 | G34: =IF(F34<=0,Params!$C$9,MIN(Params!$C$9,MAX(Params!$C$8,E34/F34))) -> 0.8 | H34: =Params!$C$12 -> 0.85 | I34: =E34*G34*H34 -> 0 | J34: =MIN(Params!$C$15,IF(I34<=Params!$C$13,I34,Params!$C$13+(I34-Params!$C$13)*Params!$C$14)) -> 0 | K34: =IF(E34>0,1,0) -> 0 | L34: =ROUNDUP(18/7,0) -> 3
A35: 19 | B35: 30 | C35: 0 | D35: 0 | E35: =B35*Params!$C$5+C35*Params!$C$6+D35*Params!$C$7 -> 30 | F35: =AVERAGE(E21:E34) -> 12.857143 | G35: =IF(F35<=0,Params!$C$9,MIN(Params!$C$9,MAX(Params!$C$8,E35/F35))) -> 1.5 | H35: =Params!$C$12 -> 0.85 | I35: =E35*G35*H35 -> 38.25 | J35: =MIN(Params!$C$15,IF(I35<=Params!$C$13,I35,Params!$C$13+(I35-Params!$C$13)*Params!$C$14)) -> 38.25 | K35: =IF(E35>0,1,0) -> 1 | L35: =ROUNDUP(19/7,0) -> 3
A36: 20 | B36: 0 | C36: 0 | D36: 0 | E36: =B36*Params!$C$5+C36*Params!$C$6+D36*Params!$C$7 -> 0 | F36: =AVERAGE(E22:E35) -> 12.857143 | G36: =IF(F36<=0,Params!$C$9,MIN(Params!$C$9,MAX(Params!$C$8,E36/F36))) -> 0.8 | H36: =Params!$C$12 -> 0.85 | I36: =E36*G36*H36 -> 0 | J36: =MIN(Params!$C$15,IF(I36<=Params!$C$13,I36,Params!$C$13+(I36-Params!$C$13)*Params!$C$14)) -> 0 | K36: =IF(E36>0,1,0) -> 0 | L36: =ROUNDUP(20/7,0) -> 3
A37: 21 | B37: 0 | C37: 0 | D37: 0 | E37: =B37*Params!$C$5+C37*Params!$C$6+D37*Params!$C$7 -> 0 | F37: =AVERAGE(E23:E36) -> 12.857143 | G37: =IF(F37<=0,Params!$C$9,MIN(Params!$C$9,MAX(Params!$C$8,E37/F37))) -> 0.8 | H37: =Params!$C$12 -> 0.85 | I37: =E37*G37*H37 -> 0 | J37: =MIN(Params!$C$15,IF(I37<=Params!$C$13,I37,Params!$C$13+(I37-Params!$C$13)*Params!$C$14)) -> 0 | K37: =IF(E37>0,1,0) -> 0 | L37: =ROUNDUP(21/7,0) -> 3
A38: 22 | B38: 0 | C38: 0 | D38: 0 | E38: =B38*Params!$C$5+C38*Params!$C$6+D38*Params!$C$7 -> 0 | F38: =AVERAGE(E24:E37) -> 12.857143 | G38: =IF(F38<=0,Params!$C$9,MIN(Params!$C$9,MAX(Params!$C$8,E38/F38))) -> 0.8 | H38: =Params!$C$12 -> 0.85 | I38: =E38*G38*H38 -> 0 | J38: =MIN(Params!$C$15,IF(I38<=Params!$C$13,I38,Params!$C$13+(I38-Params!$C$13)*Params!$C$14)) -> 0 | K38: =IF(E38>0,1,0) -> 0 | L38: =ROUNDUP(22/7,0) -> 4
A39: 23 | B39: 30 | C39: 0 | D39: 0 | E39: =B39*Params!$C$5+C39*Params!$C$6+D39*Params!$C$7 -> 30 | F39: =AVERAGE(E25:E38) -> 12.857143 | G39: =IF(F39<=0,Params!$C$9,MIN(Params!$C$9,MAX(Params!$C$8,E39/F39))) -> 1.5 | H39: =Params!$C$12 -> 0.85 | I39: =E39*G39*H39 -> 38.25 | J39: =MIN(Params!$C$15,IF(I39<=Params!$C$13,I39,Params!$C$13+(I39-Params!$C$13)*Params!$C$14)) -> 38.25 | K39: =IF(E39>0,1,0) -> 1 | L39: =ROUNDUP(23/7,0) -> 4
A40: 24 | B40: 0 | C40: 0 | D40: 0 | E40: =B40*Params!$C$5+C40*Params!$C$6+D40*Params!$C$7 -> 0 | F40: =AVERAGE(E26:E39) -> 12.857143 | G40: =IF(F40<=0,Params!$C$9,MIN(Params!$C$9,MAX(Params!$C$8,E40/F40))) -> 0.8 | H40: =Params!$C$12 -> 0.85 | I40: =E40*G40*H40 -> 0 | J40: =MIN(Params!$C$15,IF(I40<=Params!$C$13,I40,Params!$C$13+(I40-Params!$C$13)*Params!$C$14)) -> 0 | K40: =IF(E40>0,1,0) -> 0 | L40: =ROUNDUP(24/7,0) -> 4
A41: 25 | B41: 30 | C41: 0 | D41: 0 | E41: =B41*Params!$C$5+C41*Params!$C$6+D41*Params!$C$7 -> 30 | F41: =AVERAGE(E27:E40) -> 12.857143 | G41: =IF(F41<=0,Params!$C$9,MIN(Params!$C$9,MAX(Params!$C$8,E41/F41))) -> 1.5 | H41: =Params!$C$12 -> 0.85 | I41: =E41*G41*H41 -> 38.25 | J41: =MIN(Params!$C$15,IF(I41<=Params!$C$13,I41,Params!$C$13+(I41-Params!$C$13)*Params!$C$14)) -> 38.25 | K41: =IF(E41>0,1,0) -> 1 | L41: =ROUNDUP(25/7,0) -> 4
...

Sheet P3_주5러너
A1: 주5 러너 · Tier A(워치) · 시드 baseline=51.07pt/일
A2: 일 | B2: 걷기(분) | C2: 러닝(분) | D2: 근력(분) | E2: 기본점수 | F2: 14일평균 | G2: 개인계수 | H2: 신뢰계수 | I2: raw XP | J2: 일일 XP | K2: 활동 | L2: 주차
A3: 기준 D-14 | E3: 51.07
A4: 기준 D-13 | E4: 51.07
A5: 기준 D-12 | E5: 51.07
A6: 기준 D-11 | E6: 51.07
A7: 기준 D-10 | E7: 51.07
A8: 기준 D-9 | E8: 51.07
A9: 기준 D-8 | E9: 51.07
A10: 기준 D-7 | E10: 51.07
A11: 기준 D-6 | E11: 51.07
A12: 기준 D-5 | E12: 51.07
A13: 기준 D-4 | E13: 51.07
A14: 기준 D-3 | E14: 51.07
... A16: 기준 D-1 | E16: 51.07
A17: 1 | B17: 0 | C17: 35 | D17: 0 | E17: =B17*Params!$C$5+C17*Params!$C$6+D17*Params!$C$7 -> 70 | F17: =AVERAGE(E3:E16) -> 51.07 | G17: =IF(F17<=0,Params!$C$9,MIN(Params!$C$9,MAX(Params!$C$8,E17/F17))) -> 1.3706677 | H17: =Params!$C$11 -> 1 | I17: =E17*G17*H17 -> 95.94674 | J17: =MIN(Params!$C$15,IF(I17<=Params!$C$13,I17,Params!$C$13+(I17-Params!$C$13)*Params!$C$14)) -> 95.94674 | K17: =IF(E17>0,1,0) -> 1 | L17: =ROUNDUP(1/7,0) -> 1
A18: 2 | B18: 0 | C18: 0 | D18: 0 | E18: =B18*Params!$C$5+C18*Params!$C$6+D18*Params!$C$7 -> 0 | F18: =AVERAGE(E4:E17) -> 52.422143 | G18: =IF(F18<=0,Params!$C$9,MIN(Params!$C$9,MAX(Params!$C$8,E18/F18))) -> 0.8 | H18: =Params!$C$11 -> 1 | I18: =E18*G18*H18 -> 0 | J18: =MIN(Params!$C$15,IF(I18<=Params!$C$13,I18,Params!$C$13+(I18-Params!$C$13)*Params!$C$14)) -> 0 | K18: =IF(E18>0,1,0) -> 0 | L18: =ROUNDUP(2/7,0) -> 1
A19: 3 | B19: 0 | C19: 35 | D19: 0 | E19: =B19*Params!$C$5+C19*Params!$C$6+D19*Params!$C$7 -> 70 | F19: =AVERAGE(E5:E18) -> 48.774286 | G19: =IF(F19<=0,Params!$C$9,MIN(Params!$C$9,MAX(Params!$C$8,E19/F19))) -> 1.4351825 | H19: =Params!$C$11 -> 1 | I19: =E19*G19*H19 -> 100.46277 | J19: =MIN(Params!$C$15,IF(I19<=Params!$C$13,I19,Params!$C$13+(I19-Params!$C$13)*Params!$C$14)) -> 100.46277 | K19: =IF(E19>0,1,0) -> 1 | L19: =ROUNDUP(3/7,0) -> 1
A20: 4 | B20: 0 | C20: 30 | D20: 0 | E20: =B20*Params!$C$5+C20*Params!$C$6+D20*Params!$C$7 -> 60 | F20: =AVERAGE(E6:E19) -> 50.126429 | G20: =IF(F20<=0,Params!$C$9,MIN(Params!$C$9,MAX(Params!$C$8,E20/F20))) -> 1.1969734 | H20: =Params!$C$11 -> 1 | I20: =E20*G20*H20 -> 71.818402 | J20: =MIN(Params!$C$15,IF(I20<=Params!$C$13,I20,Params!$C$13+(I20-Params!$C$13)*Params!$C$14)) -> 71.818402 | K20: =IF(E20>0,1,0) -> 1 | L20: =ROUNDUP(4/7,0) -> 1
A21: 5 | B21: 0 | C21: 40 | D21: 0 | E21: =B21*Params!$C$5+C21*Params!$C$6+D21*Params!$C$7 -> 80 | F21: =AVERAGE(E7:E20) -> 50.764286 | G21: =IF(F21<=0,Params!$C$9,MIN(Params!$C$9,MAX(Params!$C$8,E21/F21))) -> 1.5 | H21: =Params!$C$11 -> 1 | I21: =E21*G21*H21 -> 120 | J21: =MIN(Params!$C$15,IF(I21<=Params!$C$13,I21,Params!$C$13+(I21-Params!$C$13)*Params!$C$14)) -> 120 | K21: =IF(E21>0,1,0) -> 1 | L21: =ROUNDUP(5/7,0) -> 1
A22: 6 | B22: 0 | C22: 0 | D22: 0 | E22: =B22*Params!$C$5+C22*Params!$C$6+D22*Params!$C$7 -> 0 | F22: =AVERAGE(E8:E21) -> 52.830714 | G22: =IF(F22<=0,Params!$C$9,MIN(Params!$C$9,MAX(Params!$C$8,E22/F22))) -> 0.8 | H22: =Params!$C$11 -> 1 | I22: =E22*G22*H22 -> 0 | J22: =MIN(Params!$C$15,IF(I22<=Params!$C$13,I22,Params!$C$13+(I22-Params!$C$13)*Params!$C$14)) -> 0 | K22: =IF(E22>0,1,0) -> 0 | L22: =ROUNDUP(6/7,0) -> 1
A23: 7 | B23: 0 | C23: 35 | D23: 0 | E23: =B23*Params!$C$5+C23*Params!$C$6+D23*Params!$C$7 -> 70 | F23: =AVERAGE(E9:E22) -> 49.182857 | G23: =IF(F23<=0,Params!$C$9,MIN(Params!$C$9,MAX(Params!$C$8,E23/F23))) -> 1.4232601 | H23: =Params!$C$11 -> 1 | I23: =E23*G23*H23 -> 99.62821 | J23: =MIN(Params!$C$15,IF(I23<=Params!$C$13,I23,Params!$C$13+(I23-Params!$C$13)*Params!$C$14)) -> 99.62821 | K23: =IF(E23>0,1,0) -> 1 | L23: =ROUNDUP(7/7,0) -> 1
A24: 8 | B24: 0 | C24: 38 | D24: 0 | E24: =B24*Params!$C$5+C24*Params!$C$6+D24*Params!$C$7 -> 76 | F24: =AVERAGE(E10:E23) -> 50.535 | G24: =IF(F24<=0,Params!$C$9,MIN(Params!$C$9,MAX(Params!$C$8,E24/F24))) -> 1.5 | H24: =Params!$C$11 -> 1 | I24: =E24*G24*H24 -> 114 | J24: =MIN(Params!$C$15,IF(I24<=Params!$C$13,I24,Params!$C$13+(I24-Params!$C$13)*Params!$C$14)) -> 114 | K24: =IF(E24>0,1,0) -> 1 | L24: =ROUNDUP(8/7,0) -> 2
A25: 9 | B25: 0 | C25: 0 | D25: 0 | E25: =B25*Params!$C$5+C25*Params!$C$6+D25*Params!$C$7 -> 0 | F25: =AVERAGE(E11:E24) -> 52.315714 | G25: =IF(F25<=0,Params!$C$9,MIN(Params!$C$9,MAX(Params!$C$8,E25/F25))) -> 0.8 | H25: =Params!$C$11 -> 1 | I25: =E25*G25*H25 -> 0 | J25: =MIN(Params!$C$15,IF(I25<=Params!$C$13,I25,Params!$C$13+(I25-Params!$C$13)*Params!$C$14)) -> 0 | K25: =IF(E25>0,1,0) -> 0 | L25: =ROUNDUP(9/7,0) -> 2
A26: 10 | B26: 0 | C26: 32 | D26: 0 | E26: =B26*Params!$C$5+C26*Params!$C$6+D26*Params!$C$7 -> 64 | F26: =AVERAGE(E12:E25) -> 48.667857 | G26: =IF(F26<=0,Params!$C$9,MIN(Params!$C$9,MAX(Params!$C$8,E26/F26))) -> 1.3150363 | H26: =Params!$C$11 -> 1 | I26: =E26*G26*H26 -> 84.162325 | J26: =MIN(Params!$C$15,IF(I26<=Params!$C$13,I26,Params!$C$13+(I26-Params!$C$13)*Params!$C$14)) -> 84.162325 | K26: =IF(E26>0,1,0) -> 1 | L26: =ROUNDUP(10/7,0) -> 2
A27: 11 | B27: 0 | C27: 35 | D27: 0 | E27: =B27*Params!$C$5+C27*Params!$C$6+D27*Params!$C$7 -> 70 | F27: =AVERAGE(E13:E26) -> 49.591429 | G27: =IF(F27<=0,Params!$C$9,MIN(Params!$C$9,MAX(Params!$C$8,E27/F27))) -> 1.4115343 | H27: =Params!$C$11 -> 1 | I27: =E27*G27*H27 -> 98.807398 | J27: =MIN(Params!$C$15,IF(I27<=Params!$C$13,I27,Params!$C$13+(I27-Params!$C$13)*Params!$C$14)) -> 98.807398 | K27: =IF(E27>0,1,0) -> 1 | L27: =ROUNDUP(11/7,0) -> 2
A28: 12 | B28: 0 | C28: 40 | D28: 0 | E28: =B28*Params!$C$5+C28*Params!$C$6+D28*Params!$C$7 -> 80 | F28: =AVERAGE(E14:E27) -> 50.943571 | G28: =IF(F28<=0,Params!$C$9,MIN(Params!$C$9,MAX(Params!$C$8,E28/F28))) -> 1.5 | H28: =Params!$C$11 -> 1 | I28: =E28*G28*H28 -> 120 | J28: =MIN(Params!$C$15,IF(I28<=Params!$C$13,I28,Params!$C$13+(I28-Params!$C$13)*Params!$C$14)) -> 120 | K28: =IF(E28>0,1,0) -> 1 | L28: =ROUNDUP(12/7,0) -> 2
A29: 13 | B29: 0 | C29: 0 | D29: 0 | E29: =B29*Params!$C$5+C29*Params!$C$6+D29*Params!$C$7 -> 0 | F29: =AVERAGE(E15:E28) -> 53.01 | G29: =IF(F29<=0,Params!$C$9,MIN(Params!$C$9,MAX(Params!$C$8,E29/F29))) -> 0.8 | H29: =Params!$C$11 -> 1 | I29: =E29*G29*H29 -> 0 | J29: =MIN(Params!$C$15,IF(I29<=Params!$C$13,I29,Params!$C$13+(I29-Params!$C$13)*Params!$C$14)) -> 0 | K29: =IF(E29>0,1,0) -> 0 | L29: =ROUNDUP(13/7,0) -> 2
A30: 14 | B30: 0 | C30: 33 | D30: 0 | E30: =B30*Params!$C$5+C30*Params!$C$6+D30*Params!$C$7 -> 66 | F30: =AVERAGE(E16:E29) -> 49.362143 | G30: =IF(F30<=0,Params!$C$9,MIN(Params!$C$9,MAX(Params!$C$8,E30/F30))) -> 1.337057 | H30: =Params!$C$11 -> 1 | I30: =E30*G30*H30 -> 88.245764 | J30: =MIN(Params!$C$15,IF(I30<=Params!$C$13,I30,Params!$C$13+(I30-Params!$C$13)*Params!$C$14)) -> 88.245764 | K30: =IF(E30>0,1,0) -> 1 | L30: =ROUNDUP(14/7,0) -> 2
A31: 15 | B31: 0 | C31: 40 | D31: 0 | E31: =B31*Params!$C$5+C31*Params!$C$6+D31*Params!$C$7 -> 80 | F31: =AVERAGE(E17:E30) -> 50.428571 | G31: =IF(F31<=0,Params!$C$9,MIN(Params!$C$9,MAX(Params!$C$8,E31/F31))) -> 1.5 | H31: =Params!$C$11 -> 1 | I31: =E31*G31*H31 -> 120 | J31: =MIN(Params!$C$15,IF(I31<=Params!$C$13,I31,Params!$C$13+(I31-Params!$C$13)*Params!$C$14)) -> 120 | K31: =IF(E31>0,1,0) -> 1 | L31: =ROUNDUP(15/7,0) -> 3
A32: 16 | B32: 0 | C32: 0 | D32: 0 | E32: =B32*Params!$C$5+C32*Params!$C$6+D32*Params!$C$7 -> 0 | F32: =AVERAGE(E18:E31) -> 51.142857 | G32: =IF(F32<=0,Params!$C$9,MIN(Params!$C$9,MAX(Params!$C$8,E32/F32))) -> 0.8 | H32: =Params!$C$11 -> 1 | I32: =E32*G32*H32 -> 0 | J32: =MIN(Params!$C$15,IF(I32<=Params!$C$13,I32,Params!$C$13+(I32-Params!$C$13)*Params!$C$14)) -> 0 | K32: =IF(E32>0,1,0) -> 0 | L32: =ROUNDUP(16/7,0) -> 3
A33: 17 | B33: 0 | C33: 35 | D33: 0 | E33: =B33*Params!$C$5+C33*Params!$C$6+D33*Params!$C$7 -> 70 | F33: =AVERAGE(E19:E32) -> 51.142857 | G33: =IF(F33<=0,Params!$C$9,MIN(Params!$C$9,MAX(Params!$C$8,E33/F33))) -> 1.3687151 | H33: =Params!$C$11 -> 1 | I33: =E33*G33*H33 -> 95.810056 | J33: =MIN(Params!$C$15,IF(I33<=Params!$C$13,I33,Params!$C$13+(I33-Params!$C$13)*Params!$C$14)) -> 95.810056 | K33: =IF(E33>0,1,0) -> 1 | L33: =ROUNDUP(17/7,0) -> 3
A34: 18 | B34: 0 | C34: 30 | D34: 0 | E34: =B34*Params!$C$5+C34*Params!$C$6+D34*Params!$C$7 -> 60 | F34: =AVERAGE(E20:E33) -> 51.142857 | G34: =IF(F34<=0,Params!$C$9,MIN(Params!$C$9,MAX(Params!$C$8,E34/F34))) -> 1.1731844 | H34: =Params!$C$11 -> 1 | I34: =E34*G34*H34 -> 70.391061 | J34: =MIN(Params!$C$15,IF(I34<=Params!$C$13,I34,Params!$C$13+(I34-Params!$C$13)*Params!$C$14)) -> 70.391061 | K34: =IF(E34>0,1,0) -> 1 | L34: =ROUNDUP(18/7,0) -> 3
A35: 19 | B35: 0 | C35: 42 | D35: 0 | E35: =B35*Params!$C$5+C35*Params!$C$6+D35*Params!$C$7 -> 84 | F35: =AVERAGE(E21:E34) -> 51.142857 | G35: =IF(F35<=0,Params!$C$9,MIN(Params!$C$9,MAX(Params!$C$8,E35/F35))) -> 1.5 | H35: =Params!$C$11 -> 1 | I35: =E35*G35*H35 -> 126 | J35: =MIN(Params!$C$15,IF(I35<=Params!$C$13,I35,Params!$C$13+(I35-Params!$C$13)*Params!$C$14)) -> 126 | K35: =IF(E35>0,1,0) -> 1 | L35: =ROUNDUP(19/7,0) -> 3
A36: 20 | B36: 0 | C36: 0 | D36: 0 | E36: =B36*Params!$C$5+C36*Params!$C$6+D36*Params!$C$7 -> 0 | F36: =AVERAGE(E22:E35) -> 51.428571 | G36: =IF(F36<=0,Params!$C$9,MIN(Params!$C$9,MAX(Params!$C$8,E36/F36))) -> 0.8 | H36: =Params!$C$11 -> 1 | I36: =E36*G36*H36 -> 0 | J36: =MIN(Params!$C$15,IF(I36<=Params!$C$13,I36,Params!$C$13+(I36-Params!$C$13)*Params!$C$14)) -> 0 | K36: =IF(E36>0,1,0) -> 0 | L36: =ROUNDUP(20/7,0) -> 3
A37: 21 | B37: 0 | C37: 36 | D37: 0 | E37: =B37*Params!$C$5+C37*Params!$C$6+D37*Params!$C$7 -> 72 | F37: =AVERAGE(E23:E36) -> 51.428571 | G37: =IF(F37<=0,Params!$C$9,MIN(Params!$C$9,MAX(Params!$C$8,E37/F37))) -> 1.4 | H37: =Params!$C$11 -> 1 | I37: =E37*G37*H37 -> 100.8 | J37: =MIN(Params!$C$15,IF(I37<=Params!$C$13,I37,Params!$C$13+(I37-Params!$C$13)*Params!$C$14)) -> 100.8 | K37: =IF(E37>0,1,0) -> 1 | L37: =ROUNDUP(21/7,0) -> 3
A38: 22 | B38: 0 | C38: 35 | D38: 0 | E38: =B38*Params!$C$5+C38*Params!$C$6+D38*Params!$C$7 -> 70 | F38: =AVERAGE(E24:E37) -> 51.571429 | G38: =IF(F38<=0,Params!$C$9,MIN(Params!$C$9,MAX(Params!$C$8,E38/F38))) -> 1.3573407 | H38: =Params!$C$11 -> 1 | I38: =E38*G38*H38 -> 95.01385 | J38: =MIN(Params!$C$15,IF(I38<=Params!$C$13,I38,Params!$C$13+(I38-Params!$C$13)*Params!$C$14)) -> 95.01385 | K38: =IF(E38>0,1,0) -> 1 | L38: =ROUNDUP(22/7,0) -> 4
A39: 23 | B39: 0 | C39: 0 | D39: 0 | E39: =B39*Params!$C$5+C39*Params!$C$6+D39*Params!$C$7 -> 0 | F39: =AVERAGE(E25:E38) -> 51.142857 | G39: =IF(F39<=0,Params!$C$9,MIN(Params!$C$9,MAX(Params!$C$8,E39/F39))) -> 0.8 | H39: =Params!$C$11 -> 1 | I39: =E39*G39*H39 -> 0 | J39: =MIN(Params!$C$15,IF(I39<=Params!$C$13,I39,Params!$C$13+(I39-Params!$C$13)*Params!$C$14)) -> 0 | K39: =IF(E39>0,1,0) -> 0 | L39: =ROUNDUP(23/7,0) -> 4
A40: 24 | B40: 0 | C40: 38 | D40: 0 | E40: =B40*Params!$C$5+C40*Params!$C$6+D40*Params!$C$7 -> 76 | F40: =AVERAGE(E26:E39) -> 51.142857 | G40: =IF(F40<=0,Params!$C$9,MIN(Params!$C$9,MAX(Params!$C$8,E40/F40))) -> 1.4860335 | H40: =Params!$C$11 -> 1 | I40: =E40*G40*H40 -> 112.93855 | J40: =MIN(Params!$C$15,IF(I40<=Params!$C$13,I40,Params!$C$13+(I40-Params!$C$13)*Params!$C$14)) -> 112.93855 | K40: =IF(E40>0,1,0) -> 1 | L40: =ROUNDUP(24/7,0) -> 4
A41: 25 | B41: 0 | C41: 32 | D41: 0 | E41: =B41*Params!$C$5+C41*Params!$C$6+D41*Params!$C$7 -> 64 | F41: =AVERAGE(E27:E40) -> 52 | G41: =IF(F41<=0,Params!$C$9,MIN(Params!$C$9,MAX(Params!$C$8,E41/F41))) -> 1.2307692 | H41: =Params!$C$11 -> 1 | I41: =E41*G41*H41 -> 78.769231 | J41: =MIN(Params!$C$15,IF(I41<=Params!$C$13,I41,Params!$C$13+(I41-Params!$C$13)*Params!$C$14)) -> 78.769231 | K41: =IF(E41>0,1,0) -> 1 | L41: =ROUNDUP(25/7,0) -> 4
...

Sheet P4_헬스만
A1: 헬스만 · Tier A(워치) · 시드 baseline=43.66pt/일
A2: 일 | B2: 걷기(분) | C2: 러닝(분) | D2: 근력(분) | E2: 기본점수 | F2: 14일평균 | G2: 개인계수 | H2: 신뢰계수 | I2: raw XP | J2: 일일 XP | K2: 활동 | L2: 주차
A3: 기준 D-14 | E3: 43.66
A4: 기준 D-13 | E4: 43.66
A5: 기준 D-12 | E5: 43.66
A6: 기준 D-11 | E6: 43.66
A7: 기준 D-10 | E7: 43.66
A8: 기준 D-9 | E8: 43.66
A9: 기준 D-8 | E9: 43.66
A10: 기준 D-7 | E10: 43.66
A11: 기준 D-6 | E11: 43.66
A12: 기준 D-5 | E12: 43.66
A13: 기준 D-4 | E13: 43.66
A14: 기준 D-3 | E14: 43.66
... A16: 기준 D-1 | E16: 43.66
A17: 1 | B17: 0 | C17: 0 | D17: 50 | E17: =B17*Params!$C$5+C17*Params!$C$6+D17*Params!$C$7 -> 75 | F17: =AVERAGE(E3:E16) -> 43.66 | G17: =IF(F17<=0,Params!$C$9,MIN(Params!$C$9,MAX(Params!$C$8,E17/F17))) -> 1.5 | H17: =Params!$C$11 -> 1 | I17: =E17*G17*H17 -> 112.5 | J17: =MIN(Params!$C$15,IF(I17<=Params!$C$13,I17,Params!$C$13+(I17-Params!$C$13)*Params!$C$14)) -> 112.5 | K17: =IF(E17>0,1,0) -> 1 | L17: =ROUNDUP(1/7,0) -> 1
A18: 2 | B18: 0 | C18: 0 | D18: 0 | E18: =B18*Params!$C$5+C18*Params!$C$6+D18*Params!$C$7 -> 0 | F18: =AVERAGE(E4:E17) -> 45.898571 | G18: =IF(F18<=0,Params!$C$9,MIN(Params!$C$9,MAX(Params!$C$8,E18/F18))) -> 0.8 | H18: =Params!$C$11 -> 1 | I18: =E18*G18*H18 -> 0 | J18: =MIN(Params!$C$15,IF(I18<=Params!$C$13,I18,Params!$C$13+(I18-Params!$C$13)*Params!$C$14)) -> 0 | K18: =IF(E18>0,1,0) -> 0 | L18: =ROUNDUP(2/7,0) -> 1
A19: 3 | B19: 0 | C19: 0 | D19: 50 | E19: =B19*Params!$C$5+C19*Params!$C$6+D19*Params!$C$7 -> 75 | F19: =AVERAGE(E5:E18) -> 42.78 | G19: =IF(F19<=0,Params!$C$9,MIN(Params!$C$9,MAX(Params!$C$8,E19/F19))) -> 1.5 | H19: =Params!$C$11 -> 1 | I19: =E19*G19*H19 -> 112.5 | J19: =MIN(Params!$C$15,IF(I19<=Params!$C$13,I19,Params!$C$13+(I19-Params!$C$13)*Params!$C$14)) -> 112.5 | K19: =IF(E19>0,1,0) -> 1 | L19: =ROUNDUP(3/7,0) -> 1
A20: 4 | B20: 0 | C20: 0 | D20: 0 | E20: =B20*Params!$C$5+C20*Params!$C$6+D20*Params!$C$7 -> 0 | F20: =AVERAGE(E6:E19) -> 45.018571 | G20: =IF(F20<=0,Params!$C$9,MIN(Params!$C$9,MAX(Params!$C$8,E20/F20))) -> 0.8 | H20: =Params!$C$11 -> 1 | I20: =E20*G20*H20 -> 0 | J20: =MIN(Params!$C$15,IF(I20<=Params!$C$13,I20,Params!$C$13+(I20-Params!$C$13)*Params!$C$14)) -> 0 | K20: =IF(E20>0,1,0) -> 0 | L20: =ROUNDUP(4/7,0) -> 1
A21: 5 | B21: 0 | C21: 0 | D21: 55 | E21: =B21*Params!$C$5+C21*Params!$C$6+D21*Params!$C$7 -> 82.5 | F21: =AVERAGE(E7:E20) -> 41.9 | G21: =IF(F21<=0,Params!$C$9,MIN(Params!$C$9,MAX(Params!$C$8,E21/F21))) -> 1.5 | H21: =Params!$C$11 -> 1 | I21: =E21*G21*H21 -> 123.75 | J21: =MIN(Params!$C$15,IF(I21<=Params!$C$13,I21,Params!$C$13+(I21-Params!$C$13)*Params!$C$14)) -> 123.75 | K21: =IF(E21>0,1,0) -> 1 | L21: =ROUNDUP(5/7,0) -> 1
A22: 6 | B22: 0 | C22: 0 | D22: 0 | E22: =B22*Params!$C$5+C22*Params!$C$6+D22*Params!$C$7 -> 0 | F22: =AVERAGE(E8:E21) -> 44.674286 | G22: =IF(F22<=0,Params!$C$9,MIN(Params!$C$9,MAX(Params!$C$8,E22/F22))) -> 0.8 | H22: =Params!$C$11 -> 1 | I22: =E22*G22*H22 -> 0 | J22: =MIN(Params!$C$15,IF(I22<=Params!$C$13,I22,Params!$C$13+(I22-Params!$C$13)*Params!$C$14)) -> 0 | K22: =IF(E22>0,1,0) -> 0 | L22: =ROUNDUP(6/7,0) -> 1
A23: 7 | B23: 0 | C23: 0 | D23: 45 | E23: =B23*Params!$C$5+C23*Params!$C$6+D23*Params!$C$7 -> 67.5 | F23: =AVERAGE(E9:E22) -> 41.555714 | G23: =IF(F23<=0,Params!$C$9,MIN(Params!$C$9,MAX(Params!$C$8,E23/F23))) -> 1.5 | H23: =Params!$C$11 -> 1 | I23: =E23*G23*H23 -> 101.25 | J23: =MIN(Params!$C$15,IF(I23<=Params!$C$13,I23,Params!$C$13+(I23-Params!$C$13)*Params!$C$14)) -> 101.25 | K23: =IF(E23>0,1,0) -> 1 | L23: =ROUNDUP(7/7,0) -> 1
A24: 8 | B24: 0 | C24: 0 | D24: 52 | E24: =B24*Params!$C$5+C24*Params!$C$6+D24*Params!$C$7 -> 78 | F24: =AVERAGE(E10:E23) -> 43.258571 | G24: =IF(F24<=0,Params!$C$9,MIN(Params!$C$9,MAX(Params!$C$8,E24/F24))) -> 1.5 | H24: =Params!$C$11 -> 1 | I24: =E24*G24*H24 -> 117 | J24: =MIN(Params!$C$15,IF(I24<=Params!$C$13,I24,Params!$C$13+(I24-Params!$C$13)*Params!$C$14)) -> 117 | K24: =IF(E24>0,1,0) -> 1 | L24: =ROUNDUP(8/7,0) -> 2
A25: 9 | B25: 0 | C25: 0 | D25: 0 | E25: =B25*Params!$C$5+C25*Params!$C$6+D25*Params!$C$7 -> 0 | F25: =AVERAGE(E11:E24) -> 45.711429 | G25: =IF(F25<=0,Params!$C$9,MIN(Params!$C$9,MAX(Params!$C$8,E25/F25))) -> 0.8 | H25: =Params!$C$11 -> 1 | I25: =E25*G25*H25 -> 0 | J25: =MIN(Params!$C$15,IF(I25<=Params!$C$13,I25,Params!$C$13+(I25-Params!$C$13)*Params!$C$14)) -> 0 | K25: =IF(E25>0,1,0) -> 0 | L25: =ROUNDUP(9/7,0) -> 2
A26: 10 | B26: 0 | C26: 0 | D26: 48 | E26: =B26*Params!$C$5+C26*Params!$C$6+D26*Params!$C$7 -> 72 | F26: =AVERAGE(E12:E25) -> 42.592857 | G26: =IF(F26<=0,Params!$C$9,MIN(Params!$C$9,MAX(Params!$C$8,E26/F26))) -> 1.5 | H26: =Params!$C$11 -> 1 | I26: =E26*G26*H26 -> 108 | J26: =MIN(Params!$C$15,IF(I26<=Params!$C$13,I26,Params!$C$13+(I26-Params!$C$13)*Params!$C$14)) -> 108 | K26: =IF(E26>0,1,0) -> 1 | L26: =ROUNDUP(10/7,0) -> 2
A27: 11 | B27: 0 | C27: 0 | D27: 0 | E27: =B27*Params!$C$5+C27*Params!$C$6+D27*Params!$C$7 -> 0 | F27: =AVERAGE(E13:E26) -> 44.617143 | G27: =IF(F27<=0,Params!$C$9,MIN(Params!$C$9,MAX(Params!$C$8,E27/F27))) -> 0.8 | H27: =Params!$C$11 -> 1 | I27: =E27*G27*H27 -> 0 | J27: =MIN(Params!$C$15,IF(I27<=Params!$C$13,I27,Params!$C$13+(I27-Params!$C$13)*Params!$C$14)) -> 0 | K27: =IF(E27>0,1,0) -> 0 | L27: =ROUNDUP(11/7,0) -> 2
A28: 12 | B28: 0 | C28: 0 | D28: 55 | E28: =B28*Params!$C$5+C28*Params!$C$6+D28*Params!$C$7 -> 82.5 | F28: =AVERAGE(E14:E27) -> 41.498571 | G28: =IF(F28<=0,Params!$C$9,MIN(Params!$C$9,MAX(Params!$C$8,E28/F28))) -> 1.5 | H28: =Params!$C$11 -> 1 | I28: =E28*G28*H28 -> 123.75 | J28: =MIN(Params!$C$15,IF(I28<=Params!$C$13,I28,Params!$C$13+(I28-Params!$C$13)*Params!$C$14)) -> 123.75 | K28: =IF(E28>0,1,0) -> 1 | L28: =ROUNDUP(12/7,0) -> 2
A29: 13 | B29: 0 | C29: 0 | D29: 0 | E29: =B29*Params!$C$5+C29*Params!$C$6+D29*Params!$C$7 -> 0 | F29: =AVERAGE(E15:E28) -> 44.272857 | G29: =IF(F29<=0,Params!$C$9,MIN(Params!$C$9,MAX(Params!$C$8,E29/F29))) -> 0.8 | H29: =Params!$C$11 -> 1 | I29: =E29*G29*H29 -> 0 | J29: =MIN(Params!$C$15,IF(I29<=Params!$C$13,I29,Params!$C$13+(I29-Params!$C$13)*Params!$C$14)) -> 0 | K29: =IF(E29>0,1,0) -> 0 | L29: =ROUNDUP(13/7,0) -> 2
A30: 14 | B30: 0 | C30: 0 | D30: 50 | E30: =B30*Params!$C$5+C30*Params!$C$6+D30*Params!$C$7 -> 75 | F30: =AVERAGE(E16:E29) -> 41.154286 | G30: =IF(F30<=0,Params!$C$9,MIN(Params!$C$9,MAX(Params!$C$8,E30/F30))) -> 1.5 | H30: =Params!$C$11 -> 1 | I30: =E30*G30*H30 -> 112.5 | J30: =MIN(Params!$C$15,IF(I30<=Params!$C$13,I30,Params!$C$13+(I30-Params!$C$13)*Params!$C$14)) -> 112.5 | K30: =IF(E30>0,1,0) -> 1 | L30: =ROUNDUP(14/7,0) -> 2
A31: 15 | B31: 0 | C31: 0 | D31: 50 | E31: =B31*Params!$C$5+C31*Params!$C$6+D31*Params!$C$7 -> 75 | F31: =AVERAGE(E17:E30) -> 43.392857 | G31: =IF(F31<=0,Params!$C$9,MIN(Params!$C$9,MAX(Params!$C$8,E31/F31))) -> 1.5 | H31: =Params!$C$11 -> 1 | I31: =E31*G31*H31 -> 112.5 | J31: =MIN(Params!$C$15,IF(I31<=Params!$C$13,I31,Params!$C$13+(I31-Params!$C$13)*Params!$C$14)) -> 112.5 | K31: =IF(E31>0,1,0) -> 1 | L31: =ROUNDUP(15/7,0) -> 3
A32: 16 | B32: 0 | C32: 0 | D32: 0 | E32: =B32*Params!$C$5+C32*Params!$C$6+D32*Params!$C$7 -> 0 | F32: =AVERAGE(E18:E31) -> 43.392857 | G32: =IF(F32<=0,Params!$C$9,MIN(Params!$C$9,MAX(Params!$C$8,E32/F32))) -> 0.8 | H32: =Params!$C$11 -> 1 | I32: =E32*G32*H32 -> 0 | J32: =MIN(Params!$C$15,IF(I32<=Params!$C$13,I32,Params!$C$13+(I32-Params!$C$13)*Params!$C$14)) -> 0 | K32: =IF(E32>0,1,0) -> 0 | L32: =ROUNDUP(16/7,0) -> 3
A33: 17 | B33: 0 | C33: 0 | D33: 55 | E33: =B33*Params!$C$5+C33*Params!$C$6+D33*Params!$C$7 -> 82.5 | F33: =AVERAGE(E19:E32) -> 43.392857 | G33: =IF(F33<=0,Params!$C$9,MIN(Params!$C$9,MAX(Params!$C$8,E33/F33))) -> 1.5 | H33: =Params!$C$11 -> 1 | I33: =E33*G33*H33 -> 123.75 | J33: =MIN(Params!$C$15,IF(I33<=Params!$C$13,I33,Params!$C$13+(I33-Params!$C$13)*Params!$C$14)) -> 123.75 | K33: =IF(E33>0,1,0) -> 1 | L33: =ROUNDUP(17/7,0) -> 3
A34: 18 | B34: 0 | C34: 0 | D34: 0 | E34: =B34*Params!$C$5+C34*Params!$C$6+D34*Params!$C$7 -> 0 | F34: =AVERAGE(E20:E33) -> 43.928571 | G34: =IF(F34<=0,Params!$C$9,MIN(Params!$C$9,MAX(Params!$C$8,E34/F34))) -> 0.8 | H34: =Params!$C$11 -> 1 | I34: =E34*G34*H34 -> 0 | J34: =MIN(Params!$C$15,IF(I34<=Params!$C$13,I34,Params!$C$13+(I34-Params!$C$13)*Params!$C$14)) -> 0 | K34: =IF(E34>0,1,0) -> 0 | L34: =ROUNDUP(18/7,0) -> 3
A35: 19 | B35: 0 | C35: 0 | D35: 50 | E35: =B35*Params!$C$5+C35*Params!$C$6+D35*Params!$C$7 -> 75 | F35: =AVERAGE(E21:E34) -> 43.928571 | G35: =IF(F35<=0,Params!$C$9,MIN(Params!$C$9,MAX(Params!$C$8,E35/F35))) -> 1.5 | H35: =Params!$C$11 -> 1 | I35: =E35*G35*H35 -> 112.5 | J35: =MIN(Params!$C$15,IF(I35<=Params!$C$13,I35,Params!$C$13+(I35-Params!$C$13)*Params!$C$14)) -> 112.5 | K35: =IF(E35>0,1,0) -> 1 | L35: =ROUNDUP(19/7,0) -> 3
A36: 20 | B36: 0 | C36: 0 | D36: 0 | E36: =B36*Params!$C$5+C36*Params!$C$6+D36*Params!$C$7 -> 0 | F36: =AVERAGE(E22:E35) -> 43.392857 | G36: =IF(F36<=0,Params!$C$9,MIN(Params!$C$9,MAX(Params!$C$8,E36/F36))) -> 0.8 | H36: =Params!$C$11 -> 1 | I36: =E36*G36*H36 -> 0 | J36: =MIN(Params!$C$15,IF(I36<=Params!$C$13,I36,Params!$C$13+(I36-Params!$C$13)*Params!$C$14)) -> 0 | K36: =IF(E36>0,1,0) -> 0 | L36: =ROUNDUP(20/7,0) -> 3
A37: 21 | B37: 0 | C37: 0 | D37: 48 | E37: =B37*Params!$C$5+C37*Params!$C$6+D37*Params!$C$7 -> 72 | F37: =AVERAGE(E23:E36) -> 43.392857 | G37: =IF(F37<=0,Params!$C$9,MIN(Params!$C$9,MAX(Params!$C$8,E37/F37))) -> 1.5 | H37: =Params!$C$11 -> 1 | I37: =E37*G37*H37 -> 108 | J37: =MIN(Params!$C$15,IF(I37<=Params!$C$13,I37,Params!$C$13+(I37-Params!$C$13)*Params!$C$14)) -> 108 | K37: =IF(E37>0,1,0) -> 1 | L37: =ROUNDUP(21/7,0) -> 3
A38: 22 | B38: 0 | C38: 0 | D38: 55 | E38: =B38*Params!$C$5+C38*Params!$C$6+D38*Params!$C$7 -> 82.5 | F38: =AVERAGE(E24:E37) -> 43.714286 | G38: =IF(F38<=0,Params!$C$9,MIN(Params!$C$9,MAX(Params!$C$8,E38/F38))) -> 1.5 | H38: =Params!$C$11 -> 1 | I38: =E38*G38*H38 -> 123.75 | J38: =MIN(Params!$C$15,IF(I38<=Params!$C$13,I38,Params!$C$13+(I38-Params!$C$13)*Params!$C$14)) -> 123.75 | K38: =IF(E38>0,1,0) -> 1 | L38: =ROUNDUP(22/7,0) -> 4
A39: 23 | B39: 0 | C39: 0 | D39: 0 | E39: =B39*Params!$C$5+C39*Params!$C$6+D39*Params!$C$7 -> 0 | F39: =AVERAGE(E25:E38) -> 44.035714 | G39: =IF(F39<=0,Params!$C$9,MIN(Params!$C$9,MAX(Params!$C$8,E39/F39))) -> 0.8 | H39: =Params!$C$11 -> 1 | I39: =E39*G39*H39 -> 0 | J39: =MIN(Params!$C$15,IF(I39<=Params!$C$13,I39,Params!$C$13+(I39-Params!$C$13)*Params!$C$14)) -> 0 | K39: =IF(E39>0,1,0) -> 0 | L39: =ROUNDUP(23/7,0) -> 4
A40: 24 | B40: 0 | C40: 0 | D40: 50 | E40: =B40*Params!$C$5+C40*Params!$C$6+D40*Params!$C$7 -> 75 | F40: =AVERAGE(E26:E39) -> 44.035714 | G40: =IF(F40<=0,Params!$C$9,MIN(Params!$C$9,MAX(Params!$C$8,E40/F40))) -> 1.5 | H40: =Params!$C$11 -> 1 | I40: =E40*G40*H40 -> 112.5 | J40: =MIN(Params!$C$15,IF(I40<=Params!$C$13,I40,Params!$C$13+(I40-Params!$C$13)*Params!$C$14)) -> 112.5 | K40: =IF(E40>0,1,0) -> 1 | L40: =ROUNDUP(24/7,0) -> 4
A41: 25 | B41: 0 | C41: 0 | D41: 0 | E41: =B41*Params!$C$5+C41*Params!$C$6+D41*Params!$C$7 -> 0 | F41: =AVERAGE(E27:E40) -> 44.25 | G41: =IF(F41<=0,Params!$C$9,MIN(Params!$C$9,MAX(Params!$C$8,E41/F41))) -> 0.8 | H41: =Params!$C$11 -> 1 | I41: =E41*G41*H41 -> 0 | J41: =MIN(Params!$C$15,IF(I41<=Params!$C$13,I41,Params!$C$13+(I41-Params!$C$13)*Params!$C$14)) -> 0 | K41: =IF(E41>0,1,0) -> 0 | L41: =ROUNDUP(25/7,0) -> 4
...

Sheet P5_들쑥날쑥
A1: 들쑥날쑥 · Tier B(폰) · 시드 baseline=29.73pt/일
A2: 일 | B2: 걷기(분) | C2: 러닝(분) | D2: 근력(분) | E2: 기본점수 | F2: 14일평균 | G2: 개인계수 | H2: 신뢰계수 | I2: raw XP | J2: 일일 XP | K2: 활동 | L2: 주차
A3: 기준 D-14 | E3: 29.73
A4: 기준 D-13 | E4: 29.73
A5: 기준 D-12 | E5: 29.73
A6: 기준 D-11 | E6: 29.73
A7: 기준 D-10 | E7: 29.73
A8: 기준 D-9 | E8: 29.73
A9: 기준 D-8 | E9: 29.73
A10: 기준 D-7 | E10: 29.73
A11: 기준 D-6 | E11: 29.73
A12: 기준 D-5 | E12: 29.73
A13: 기준 D-4 | E13: 29.73
A14: 기준 D-3 | E14: 29.73
... A16: 기준 D-1 | E16: 29.73
A17: 1 | B17: 0 | C17: 60 | D17: 0 | E17: =B17*Params!$C$5+C17*Params!$C$6+D17*Params!$C$7 -> 120 | F17: =AVERAGE(E3:E16) -> 29.73 | G17: =IF(F17<=0,Params!$C$9,MIN(Params!$C$9,MAX(Params!$C$8,E17/F17))) -> 1.5 | H17: =Params!$C$12 -> 0.85 | I17: =E17*G17*H17 -> 153 | J17: =MIN(Params!$C$15,IF(I17<=Params!$C$13,I17,Params!$C$13+(I17-Params!$C$13)*Params!$C$14)) -> 153 | K17: =IF(E17>0,1,0) -> 1 | L17: =ROUNDUP(1/7,0) -> 1
A18: 2 | B18: 0 | C18: 0 | D18: 45 | E18: =B18*Params!$C$5+C18*Params!$C$6+D18*Params!$C$7 -> 67.5 | F18: =AVERAGE(E4:E17) -> 36.177857 | G18: =IF(F18<=0,Params!$C$9,MIN(Params!$C$9,MAX(Params!$C$8,E18/F18))) -> 1.5 | H18: =Params!$C$12 -> 0.85 | I18: =E18*G18*H18 -> 86.0625 | J18: =MIN(Params!$C$15,IF(I18<=Params!$C$13,I18,Params!$C$13+(I18-Params!$C$13)*Params!$C$14)) -> 86.0625 | K18: =IF(E18>0,1,0) -> 1 | L18: =ROUNDUP(2/7,0) -> 1
A19: 3 | B19: 0 | C19: 50 | D19: 0 | E19: =B19*Params!$C$5+C19*Params!$C$6+D19*Params!$C$7 -> 100 | F19: =AVERAGE(E5:E18) -> 38.875714 | G19: =IF(F19<=0,Params!$C$9,MIN(Params!$C$9,MAX(Params!$C$8,E19/F19))) -> 1.5 | H19: =Params!$C$12 -> 0.85 | I19: =E19*G19*H19 -> 127.5 | J19: =MIN(Params!$C$15,IF(I19<=Params!$C$13,I19,Params!$C$13+(I19-Params!$C$13)*Params!$C$14)) -> 127.5 | K19: =IF(E19>0,1,0) -> 1 | L19: =ROUNDUP(3/7,0) -> 1
A20: 4 | B20: 0 | C20: 0 | D20: 0 | E20: =B20*Params!$C$5+C20*Params!$C$6+D20*Params!$C$7 -> 0 | F20: =AVERAGE(E6:E19) -> 43.895 | G20: =IF(F20<=0,Params!$C$9,MIN(Params!$C$9,MAX(Params!$C$8,E20/F20))) -> 0.8 | H20: =Params!$C$12 -> 0.85 | I20: =E20*G20*H20 -> 0 | J20: =MIN(Params!$C$15,IF(I20<=Params!$C$13,I20,Params!$C$13+(I20-Params!$C$13)*Params!$C$14)) -> 0 | K20: =IF(E20>0,1,0) -> 0 | L20: =ROUNDUP(4/7,0) -> 1
A21: 5 | B21: 0 | C21: 0 | D21: 0 | E21: =B21*Params!$C$5+C21*Params!$C$6+D21*Params!$C$7 -> 0 | F21: =AVERAGE(E7:E20) -> 41.771429 | G21: =IF(F21<=0,Params!$C$9,MIN(Params!$C$9,MAX(Params!$C$8,E21/F21))) -> 0.8 | H21: =Params!$C$12 -> 0.85 | I21: =E21*G21*H21 -> 0 | J21: =MIN(Params!$C$15,IF(I21<=Params!$C$13,I21,Params!$C$13+(I21-Params!$C$13)*Params!$C$14)) -> 0 | K21: =IF(E21>0,1,0) -> 0 | L21: =ROUNDUP(5/7,0) -> 1
A22: 6 | B22: 30 | C22: 0 | D22: 0 | E22: =B22*Params!$C$5+C22*Params!$C$6+D22*Params!$C$7 -> 30 | F22: =AVERAGE(E8:E21) -> 39.647857 | G22: =IF(F22<=0,Params!$C$9,MIN(Params!$C$9,MAX(Params!$C$8,E22/F22))) -> 0.8 | H22: =Params!$C$12 -> 0.85 | I22: =E22*G22*H22 -> 20.4 | J22: =MIN(Params!$C$15,IF(I22<=Params!$C$13,I22,Params!$C$13+(I22-Params!$C$13)*Params!$C$14)) -> 20.4 | K22: =IF(E22>0,1,0) -> 1 | L22: =ROUNDUP(6/7,0) -> 1
A23: 7 | B23: 0 | C23: 0 | D23: 0 | E23: =B23*Params!$C$5+C23*Params!$C$6+D23*Params!$C$7 -> 0 | F23: =AVERAGE(E9:E22) -> 39.667143 | G23: =IF(F23<=0,Params!$C$9,MIN(Params!$C$9,MAX(Params!$C$8,E23/F23))) -> 0.8 | H23: =Params!$C$12 -> 0.85 | I23: =E23*G23*H23 -> 0 | J23: =MIN(Params!$C$15,IF(I23<=Params!$C$13,I23,Params!$C$13+(I23-Params!$C$13)*Params!$C$14)) -> 0 | K23: =IF(E23>0,1,0) -> 0 | L23: =ROUNDUP(7/7,0) -> 1
A24: 8 | B24: 0 | C24: 0 | D24: 0 | E24: =B24*Params!$C$5+C24*Params!$C$6+D24*Params!$C$7 -> 0 | F24: =AVERAGE(E10:E23) -> 37.543571 | G24: =IF(F24<=0,Params!$C$9,MIN(Params!$C$9,MAX(Params!$C$8,E24/F24))) -> 0.8 | H24: =Params!$C$12 -> 0.85 | I24: =E24*G24*H24 -> 0 | J24: =MIN(Params!$C$15,IF(I24<=Params!$C$13,I24,Params!$C$13+(I24-Params!$C$13)*Params!$C$14)) -> 0 | K24: =IF(E24>0,1,0) -> 0 | L24: =ROUNDUP(8/7,0) -> 2
A25: 9 | B25: 0 | C25: 0 | D25: 0 | E25: =B25*Params!$C$5+C25*Params!$C$6+D25*Params!$C$7 -> 0 | F25: =AVERAGE(E11:E24) -> 35.42 | G25: =IF(F25<=0,Params!$C$9,MIN(Params!$C$9,MAX(Params!$C$8,E25/F25))) -> 0.8 | H25: =Params!$C$12 -> 0.85 | I25: =E25*G25*H25 -> 0 | J25: =MIN(Params!$C$15,IF(I25<=Params!$C$13,I25,Params!$C$13+(I25-Params!$C$13)*Params!$C$14)) -> 0 | K25: =IF(E25>0,1,0) -> 0 | L25: =ROUNDUP(9/7,0) -> 2
A26: 10 | B26: 15 | C26: 0 | D26: 0 | E26: =B26*Params!$C$5+C26*Params!$C$6+D26*Params!$C$7 -> 15 | F26: =AVERAGE(E12:E25) -> 33.296429 | G26: =IF(F26<=0,Params!$C$9,MIN(Params!$C$9,MAX(Params!$C$8,E26/F26))) -> 0.8 | H26: =Params!$C$12 -> 0.85 | I26: =E26*G26*H26 -> 10.2 | J26: =MIN(Params!$C$15,IF(I26<=Params!$C$13,I26,Params!$C$13+(I26-Params!$C$13)*Params!$C$14)) -> 10.2 | K26: =IF(E26>0,1,0) -> 1 | L26: =ROUNDUP(10/7,0) -> 2
A27: 11 | B27: 0 | C27: 0 | D27: 0 | E27: =B27*Params!$C$5+C27*Params!$C$6+D27*Params!$C$7 -> 0 | F27: =AVERAGE(E13:E26) -> 32.244286 | G27: =IF(F27<=0,Params!$C$9,MIN(Params!$C$9,MAX(Params!$C$8,E27/F27))) -> 0.8 | H27: =Params!$C$12 -> 0.85 | I27: =E27*G27*H27 -> 0 | J27: =MIN(Params!$C$15,IF(I27<=Params!$C$13,I27,Params!$C$13+(I27-Params!$C$13)*Params!$C$14)) -> 0 | K27: =IF(E27>0,1,0) -> 0 | L27: =ROUNDUP(11/7,0) -> 2
A28: 12 | B28: 0 | C28: 0 | D28: 0 | E28: =B28*Params!$C$5+C28*Params!$C$6+D28*Params!$C$7 -> 0 | F28: =AVERAGE(E14:E27) -> 30.120714 | G28: =IF(F28<=0,Params!$C$9,MIN(Params!$C$9,MAX(Params!$C$8,E28/F28))) -> 0.8 | H28: =Params!$C$12 -> 0.85 | I28: =E28*G28*H28 -> 0 | J28: =MIN(Params!$C$15,IF(I28<=Params!$C$13,I28,Params!$C$13+(I28-Params!$C$13)*Params!$C$14)) -> 0 | K28: =IF(E28>0,1,0) -> 0 | L28: =ROUNDUP(12/7,0) -> 2
A29: 13 | B29: 0 | C29: 0 | D29: 0 | E29: =B29*Params!$C$5+C29*Params!$C$6+D29*Params!$C$7 -> 0 | F29: =AVERAGE(E15:E28) -> 27.997143 | G29: =IF(F29<=0,Params!$C$9,MIN(Params!$C$9,MAX(Params!$C$8,E29/F29))) -> 0.8 | H29: =Params!$C$12 -> 0.85 | I29: =E29*G29*H29 -> 0 | J29: =MIN(Params!$C$15,IF(I29<=Params!$C$13,I29,Params!$C$13+(I29-Params!$C$13)*Params!$C$14)) -> 0 | K29: =IF(E29>0,1,0) -> 0 | L29: =ROUNDUP(13/7,0) -> 2
A30: 14 | B30: 0 | C30: 0 | D30: 0 | E30: =B30*Params!$C$5+C30*Params!$C$6+D30*Params!$C$7 -> 0 | F30: =AVERAGE(E16:E29) -> 25.873571 | G30: =IF(F30<=0,Params!$C$9,MIN(Params!$C$9,MAX(Params!$C$8,E30/F30))) -> 0.8 | H30: =Params!$C$12 -> 0.85 | I30: =E30*G30*H30 -> 0 | J30: =MIN(Params!$C$15,IF(I30<=Params!$C$13,I30,Params!$C$13+(I30-Params!$C$13)*Params!$C$14)) -> 0 | K30: =IF(E30>0,1,0) -> 0 | L30: =ROUNDUP(14/7,0) -> 2
A31: 15 | B31: 0 | C31: 0 | D31: 60 | E31: =B31*Params!$C$5+C31*Params!$C$6+D31*Params!$C$7 -> 90 | F31: =AVERAGE(E17:E30) -> 23.75 | G31: =IF(F31<=0,Params!$C$9,MIN(Params!$C$9,MAX(Params!$C$8,E31/F31))) -> 1.5 | H31: =Params!$C$12 -> 0.85 | I31: =E31*G31*H31 -> 114.75 | J31: =MIN(Params!$C$15,IF(I31<=Params!$C$13,I31,Params!$C$13+(I31-Params!$C$13)*Params!$C$14)) -> 114.75 | K31: =IF(E31>0,1,0) -> 1 | L31: =ROUNDUP(15/7,0) -> 3
A32: 16 | B32: 0 | C32: 0 | D32: 0 | E32: =B32*Params!$C$5+C32*Params!$C$6+D32*Params!$C$7 -> 0 | F32: =AVERAGE(E18:E31) -> 21.607143 | G32: =IF(F32<=0,Params!$C$9,MIN(Params!$C$9,MAX(Params!$C$8,E32/F32))) -> 0.8 | H32: =Params!$C$12 -> 0.85 | I32: =E32*G32*H32 -> 0 | J32: =MIN(Params!$C$15,IF(I32<=Params!$C$13,I32,Params!$C$13+(I32-Params!$C$13)*Params!$C$14)) -> 0 | K32: =IF(E32>0,1,0) -> 0 | L32: =ROUNDUP(16/7,0) -> 3
A33: 17 | B33: 0 | C33: 70 | D33: 0 | E33: =B33*Params!$C$5+C33*Params!$C$6+D33*Params!$C$7 -> 140 | F33: =AVERAGE(E19:E32) -> 16.785714 | G33: =IF(F33<=0,Params!$C$9,MIN(Params!$C$9,MAX(Params!$C$8,E33/F33))) -> 1.5 | H33: =Params!$C$12 -> 0.85 | I33: =E33*G33*H33 -> 178.5 | J33: =MIN(Params!$C$15,IF(I33<=Params!$C$13,I33,Params!$C$13+(I33-Params!$C$13)*Params!$C$14)) -> 178.5 | K33: =IF(E33>0,1,0) -> 1 | L33: =ROUNDUP(17/7,0) -> 3
A34: 18 | B34: 0 | C34: 0 | D34: 0 | E34: =B34*Params!$C$5+C34*Params!$C$6+D34*Params!$C$7 -> 0 | F34: =AVERAGE(E20:E33) -> 19.642857 | G34: =IF(F34<=0,Params!$C$9,MIN(Params!$C$9,MAX(Params!$C$8,E34/F34))) -> 0.8 | H34: =Params!$C$12 -> 0.85 | I34: =E34*G34*H34 -> 0 | J34: =MIN(Params!$C$15,IF(I34<=Params!$C$13,I34,Params!$C$13+(I34-Params!$C$13)*Params!$C$14)) -> 0 | K34: =IF(E34>0,1,0) -> 0 | L34: =ROUNDUP(18/7,0) -> 3
A35: 19 | B35: 0 | C35: 0 | D35: 0 | E35: =B35*Params!$C$5+C35*Params!$C$6+D35*Params!$C$7 -> 0 | F35: =AVERAGE(E21:E34) -> 19.642857 | G35: =IF(F35<=0,Params!$C$9,MIN(Params!$C$9,MAX(Params!$C$8,E35/F35))) -> 0.8 | H35: =Params!$C$12 -> 0.85 | I35: =E35*G35*H35 -> 0 | J35: =MIN(Params!$C$15,IF(I35<=Params!$C$13,I35,Params!$C$13+(I35-Params!$C$13)*Params!$C$14)) -> 0 | K35: =IF(E35>0,1,0) -> 0 | L35: =ROUNDUP(19/7,0) -> 3
A36: 20 | B36: 0 | C36: 55 | D36: 0 | E36: =B36*Params!$C$5+C36*Params!$C$6+D36*Params!$C$7 -> 110 | F36: =AVERAGE(E22:E35) -> 19.642857 | G36: =IF(F36<=0,Params!$C$9,MIN(Params!$C$9,MAX(Params!$C$8,E36/F36))) -> 1.5 | H36: =Params!$C$12 -> 0.85 | I36: =E36*G36*H36 -> 140.25 | J36: =MIN(Params!$C$15,IF(I36<=Params!$C$13,I36,Params!$C$13+(I36-Params!$C$13)*Params!$C$14)) -> 140.25 | K36: =IF(E36>0,1,0) -> 1 | L36: =ROUNDUP(20/7,0) -> 3
A37: 21 | B37: 0 | C37: 0 | D37: 0 | E37: =B37*Params!$C$5+C37*Params!$C$6+D37*Params!$C$7 -> 0 | F37: =AVERAGE(E23:E36) -> 25.357143 | G37: =IF(F37<=0,Params!$C$9,MIN(Params!$C$9,MAX(Params!$C$8,E37/F37))) -> 0.8 | H37: =Params!$C$12 -> 0.85 | I37: =E37*G37*H37 -> 0 | J37: =MIN(Params!$C$15,IF(I37<=Params!$C$13,I37,Params!$C$13+(I37-Params!$C$13)*Params!$C$14)) -> 0 | K37: =IF(E37>0,1,0) -> 0 | L37: =ROUNDUP(21/7,0) -> 3
A38: 22 | B38: 30 | C38: 0 | D38: 0 | E38: =B38*Params!$C$5+C38*Params!$C$6+D38*Params!$C$7 -> 30 | F38: =AVERAGE(E24:E37) -> 25.357143 | G38: =IF(F38<=0,Params!$C$9,MIN(Params!$C$9,MAX(Params!$C$8,E38/F38))) -> 1.1830986 | H38: =Params!$C$12 -> 0.85 | I38: =E38*G38*H38 -> 30.169014 | J38: =MIN(Params!$C$15,IF(I38<=Params!$C$13,I38,Params!$C$13+(I38-Params!$C$13)*Params!$C$14)) -> 30.169014 | K38: =IF(E38>0,1,0) -> 1 | L38: =ROUNDUP(22/7,0) -> 4
A39: 23 | B39: 0 | C39: 0 | D39: 0 | E39: =B39*Params!$C$5+C39*Params!$C$6+D39*Params!$C$7 -> 0 | F39: =AVERAGE(E25:E38) -> 27.5 | G39: =IF(F39<=0,Params!$C$9,MIN(Params!$C$9,MAX(Params!$C$8,E39/F39))) -> 0.8 | H39: =Params!$C$12 -> 0.85 | I39: =E39*G39*H39 -> 0 | J39: =MIN(Params!$C$15,IF(I39<=Params!$C$13,I39,Params!$C$13+(I39-Params!$C$13)*Params!$C$14)) -> 0 | K39: =IF(E39>0,1,0) -> 0 | L39: =ROUNDUP(23/7,0) -> 4
A40: 24 | B40: 0 | C40: 0 | D40: 40 | E40: =B40*Params!$C$5+C40*Params!$C$6+D40*Params!$C$7 -> 60 | F40: =AVERAGE(E26:E39) -> 27.5 | G40: =IF(F40<=0,Params!$C$9,MIN(Params!$C$9,MAX(Params!$C$8,E40/F40))) -> 1.5 | H40: =Params!$C$12 -> 0.85 | I40: =E40*G40*H40 -> 76.5 | J40: =MIN(Params!$C$15,IF(I40<=Params!$C$13,I40,Params!$C$13+(I40-Params!$C$13)*Params!$C$14)) -> 76.5 | K40: =IF(E40>0,1,0) -> 1 | L40: =ROUNDUP(24/7,0) -> 4
A41: 25 | B41: 0 | C41: 0 | D41: 0 | E41: =B41*Params!$C$5+C41*Params!$C$6+D41*Params!$C$7 -> 0 | F41: =AVERAGE(E27:E40) -> 30.714286 | G41: =IF(F41<=0,Params!$C$9,MIN(Params!$C$9,MAX(Params!$C$8,E41/F41))) -> 0.8 | H41: =Params!$C$12 -> 0.85 | I41: =E41*G41*H41 -> 0 | J41: =MIN(Params!$C$15,IF(I41<=Params!$C$13,I41,Params!$C$13+(I41-Params!$C$13)*Params!$C$14)) -> 0 | K41: =IF(E41>0,1,0) -> 0 | L41: =ROUNDUP(25/7,0) -> 4
...
